Workbook

Sheet CHECKSHEET
A2: Pre-commissioning Preliminary Check List - Walkdown (PS4/PS5)
A3: Sr. no | B3: Item / Activity | C3: Check Point for attendance at site | D3: Power Gen | E3: PS-4 Sub-system No. | F3: PS-5 Sub-system No. | G3: Comments
A4: 1 | B4: Injector tip Cooling Module (Repeated for All Skids) | D4: PG | E4: PS4-60-35/36/37/38/39/40/41 | F4: PS5-60-35/36/37/38/39/40/41 | H4: Milestone B | I4: Milestone D | J4: Milestone E
A5: 2 | B5: Alternator bearing cooling skid (Repeated for All Skids) | D5: PG | E5: PS4-60-01/04/07/10/13/16/19 | F5: PS5-60-01/04/07/10/13/16/19 | H5: Milestone B | I5: Milestone D | J5: Milestone E
A6: 3 | B6: Lube oil separator module (Repeated for All Skids) | D6: PG | E6: PS4-60-49/50/51/52/53/54/55 | F6: PS5-60-49/50/51/52/53/54/55 | H6: Milestone B | I6: Milestone D | J6: Milestone E
A7: 4 | B7: Oil mist eliminator (Vent Purifier) (Repeated for All Units) | D7: PG | E7: PS4-60-42/43/44/45/46/47/48 | F7: PS5-60-42/43/44/45/46/47/48 | H7: Milestone B | I7: Milestone D | J7: Milestone E
A8: 5 | B8: External Cooler Skid (Repeated for All Skids) | D8: PG | E8: PS4-60-35/36/37/38/39/40/41 | F8: PS5-60-35/36/37/38/39/40/41 | H8: Milestone B | I8: Milestone D | J8: Milestone E
A9: 6 | B9: Engine Cooling Radiator (Repeated for All Skids) | D9: PG | E9: PS4-60-70/71/72/73/74/75/76 | F9: PS5-60-70/71/72/73/74/75/76 | H9: Milestone B | I9: Milestone D | J9: Milestone E
A10: 7 | B10: Cooling water expansion Tank(s) (Repeated for All Skids) | D10: PG | E10: PS4-60-70/71/72/73/74/75/76 | F10: PS5-60-70/71/72/73/74/75/76 | H10: Milestone B | I10: Milestone D | J10: Milestone E
A11: 8 | B11: Fuel Conditioning module unit (FCU) (Repeated for All Skids) | D11: PG | E11: PS4-60-56/58/60/62/64/66/68 | F11: PS5-60-56/58/60/62/64/66/68 | H11: Milestone B | I11: Milestone D | J11: Milestone E
A12: 9 | B12: Starting Compressed air skid | D12: PG | E12: PS4-60-27 | F12: PS5-60-27 | H12: Milestone B
A13: 10 | B13: Starting Compressed air Bottles | D13: PG | E13: PS4-60-27 | F13: PS5-60-27 | H13: Milestone B
A14: 11 | B14: Instrument Air Compressor Skid | D14: PG | E14: PS4-60-26 | F14: PS5-60-26 | H14: Milestone B
A15: 12 | B15: Crude separator module (A/B) | D15: PG | E15: PS4-71-06 | F15: PS5-71-06 | H15: Milestone H
A16: 13 | B16: Diesel oil separator module | D16: PG | E16: PS4-71-22 | F16: PS5-71-22 | H16: Milestone B
A17: 14 | B17: Crude pre-pressure module | D17: PG | E17: PS4-71-08 | F17: PS5-71-08 | H17: Milestone H
A18: 15 | B18: Diesel oil pre-pressure module | D18: PG | E18: PS4-71-22 | F18: PS5-71-22 | H18: Milestone B
A19: 16 | B19: Self supporting exhaust Chimney (repeated) | D19: PG | E19: PS4-60-35/36/37/38/39/40/41 | F19: PS5-60-35/36/37/38/39/40/41 | H19: Milestone B | I19: Milestone D | J19: Milestone E
A20: 17 | B20: Exhaust gas silencer (Repeated) | D20: PG | E20: PS4-60-35/36/37/38/39/40/41 | F20: PS5-60-35/36/37/38/39/40/41 | H20: Milestone B | I20: Milestone D | J20: Milestone E
A21: 18 | B21: Exhaust Line ducting (Repeated) | D21: PG | E21: PS4-60-35/36/37/38/39/40/41 | F21: PS5-60-35/36/37/38/39/40/41 | H21: Milestone B | I21: Milestone D | J21: Milestone E
A22: 19 | B22: Air Intake ducting (Repeated) | D22: PG | E22: PS4-60-35/36/37/38/39/40/41 | F22: PS5-60-35/36/37/38/39/40/41 | H22: Milestone B | I22: Milestone D | J22: Milestone E
A23: 20 | B23: Engine MCC - CRO Generator set | D23: PG | E23: PS4-60-03/06/09/12/15/18/21 | F23: PS5-60-03/06/09/12/15/18/21 | H23: Milestone B | I23: Milestone D | J23: Milestone E
A24: 21 | B24: Power Generation Common/Treatment MCC | D24: PG | E24: PS4-60-22 | F24: PS5-60-22 | H24: Milestone B
A25: 22 | B25: Local display panel LDP Generator set | D25: PG | E25: PS4-60-01/04/07/10/13/16/19 | F25: PS5-60-01/04/07/10/13/16/19 | H25: Milestone B | I25: Milestone D | J25: Milestone E
A26: 23 | B26: GCP Generator Set | D26: PG | E26: PS4-60-02/05/08/11/14/17/20 | F26: PS5-60-02/05/08/11/14/17/20 | H26: Milestone B | I26: Milestone D | J26: Milestone E
A27: 24 | B27: Master Control panel | D27: PG | E27: PS4-60-22 | F27: PS5-60-22 | H27: Milestone B
A28: 25 | B28: VTMS Vibration and temperature monitoring System | D28: PG | E28: PS4-60-01/10/16 | F28: PS5-60-01/10/16 | H28: Milestone B | I28: Milestone D
A29: 26 | B29: RAP remote access panel | D29: PG | E29: PS4-60-22 | F29: PS5-60-22 | H29: Milestone B
A30: 27 | B30: Gas detection panel | D30: PG | E30: PS4-03-14 | F30: PS5-03-14 | H30: Milestone E
A31: 28 | B31: Power Step-up Transformer (PS4/PS5 only) | D31: PG | E31: PS4-60-01/04/07/10/13/16/19 | F31: PS5-60-01/04/07/10/13/16/19 | H31: Milestone B | I31: Milestone D | J31: Milestone E
A32: 29 | B32: Crude oil CFO- Separator Control Panel | D32: PG | E32: PS4-71-09 | F32: PS5-71-09 | H32: Milestone H
A33: 30 | B33: Diesel Fuel oil DFO Control Panels | D33: PG | E33: PS4-71-23 | F33: PS5-71-23 | H33: Milestone B
A34: 31 | B34: FCU Control Panel | D34: PG | E34: PS4-60-57/59/61/63/65/67/69 | F34: PS5-60-57/59/61/63/65/67/69 | H34: Milestone B | I34: Milestone D | J34: Milestone E
A35: 32 | B35: NGRs (PS4/PS5 only) | D35: PG | E35: PS4-60-01/04/07/10/13/16/19 | F35: PS5-60-01/04/07/10/13/16/19 | H35: Milestone B | I35: Milestone D | J35: Milestone E
E36: PS5-05-01,02

Sheet ITR SUMMARY
C4: Responsible Company : CPP AGI-VENDOR-MANTRAC CHECKLIST SUMMERY
C5: Discipline | D5: Total | E5: Closed | F5: % | G5: Open | I5: CUT OFF DATE-03-JULY-2026
I6: 27 June | J6: 28 June | K6: 29 June | L6: 30 June | M6: 1 July | N6: 2 July | O6: 3 July | P6: TOTAL | V6: MONTH | W6: TOTAL NO SS | X6: RFC SIGNED | Y6: TOTAL ITRS | Z6: TOTAL CLOSED | AA6: BALANCE | AB6: % COMPLETION | AC6: ITR CLOSED THIS WEEK
C7: CPP | V7: JUNE | W7: 10 | X7: 0 | Y7: =COUNTIFS('DETAILED ITR LIST'!#REF!,"JUNE") -> #REF! | Z7: =COUNTIFS('DETAILED ITR LIST'!#REF!,"JUNE",'DETAILED ITR LIST'!AC:AC,"CLOSED") -> #REF! | AA7: =Y7-Z7 -> #REF! | AB7: =Z7/Y7 -> #REF! | AC7: 29
C8: Mechanical | D8: =COUNTIF('DETAILED ITR LIST'!I:I,"M") -> 202 | E8: =COUNTIFS('DETAILED ITR LIST'!I:I,"M",'DETAILED ITR LIST'!AC:AC,"Closed") -> 202 | F8: =E8/D8 -> 1 | G8: =D8-E8 -> 0 | L8: 14 | P8: =SUM(I8:O8) -> 14 | V8: SEPTEMBER | W8: 53 | X8: 0 | Y8: =COUNTIFS('DETAILED ITR LIST'!#REF!,"SEPTEMBER") -> #REF! | Z8: =COUNTIFS('DETAILED ITR LIST'!#REF!,"SEPTEMBER",'DETAILED ITR LIST'!AC:AC,"CLOSED") -> #REF! | AA8: =Y8-Z8 -> #REF! | AB8: =Z8/Y8 -> #REF! | AC8: 1
C9: Piping & Vessel | D9: =COUNTIF('DETAILED ITR LIST'!I:I,"P") -> 995 | E9: =COUNTIFS('DETAILED ITR LIST'!I:I,"P",'DETAILED ITR LIST'!AC:AC,"Closed") -> 578 | F9: =E9/D9 -> 0.58090452 | G9: =D9-E9 -> 417 | I9: 1 | L9: 9 | M9: 4 | N9: 19 | O9: 8 | P9: =SUM(I9:O9) -> 41 | V9: OCTOBER | W9: 7 | X9: 0 | Y9: =COUNTIFS('DETAILED ITR LIST'!#REF!,"OCTOBER") -> #REF! | Z9: =COUNTIFS('DETAILED ITR LIST'!#REF!,"OCTOBER",'DETAILED ITR LIST'!AC:AC,"CLOSED") -> #REF! | AA9: =Y9-Z9 -> #REF! | AB9: =Z9/Y9 -> #REF! | AC9: 0
C10: Total | D10: =SUM(D8:D9) -> 1197 | E10: =SUM(E8:E9) -> 780 | F10: =E10/D10 -> 0.65162907 | G10: =SUM(G8:G9) -> 417 | H10: =SUM(H8:H9) -> 0 | I10: =SUM(I8:I9) -> 1 | J10: =SUM(J8:J9) -> 0 | K10: =SUM(K8:K9) -> 0 | L10: =SUM(L8:L9) -> 23 | M10: =SUM(M8:M9) -> 4 | N10: =SUM(N8:N9) -> 19 | ... P10: =SUM(P8:P9) -> 55
C11: EIT | V11: MONTH | W11: TOTAL NO SS | X11: RFC SIGNED | Y11: TOTAL ITRS | Z11: TOTAL CLOSED | AA11: BALANCE | AB11: % COMPLETION | AC11: ITR CLOSED THIS WEEK
C12: Electrical | D12: =COUNTIF('DETAILED ITR LIST'!I:I,"E") -> 1451 | E12: =COUNTIFS('DETAILED ITR LIST'!I:I,"E",'DETAILED ITR LIST'!AC:AC,"Closed") -> 300 | F12: =E12/D12 -> 0.20675396 | G12: =D12-E12 -> 1151 | I12: 15 | M12: 35 | O12: 8 | P12: =SUM(I12:O12) -> 58 | V12: JUNE | W12: 9 | X12: 0 | Y12: 437 | Z12: 47 | AA12: =Y12-Z12 -> 390 | AB12: =Z12/Y12 -> 0.10755149 | AC12: 29
C13: Instrumentation | D13: =COUNTIF('DETAILED ITR LIST'!I:I,"I") -> 1366 | E13: =COUNTIFS('DETAILED ITR LIST'!I:I,"I",'DETAILED ITR LIST'!AC:AC,"Closed") -> 18 | F13: =E13/D13 -> 0.01317716 | G13: =D13-E13 -> 1348 | M13: 18 | P13: =SUM(I13:O13) -> 18 | V13: JULY | W13: 48 | X13: 0 | Y13: 2705 | Z13: 306 | AA13: =Y13-Z13 -> 2399 | AB13: =Z13/Y13 -> 0.11312384 | AC13: 33
C14: Telecom | D14: =COUNTIF('DETAILED ITR LIST'!I:I,"T") -> 130 | E14: =COUNTIFS('DETAILED ITR LIST'!I:I,"T",'DETAILED ITR LIST'!AC:AC,"Closed") -> 0 | F14: =E14/D14 -> 0 | G14: =D14-E14 -> 130 | P14: =SUM(I14:O14) -> 0 | V14: AUGUST | W14: 129 | X14: 0 | Y14: 6505 | Z14: 874 | AA14: =Y14-Z14 -> 5631 | AB14: =Z14/Y14 -> 0.13435819 | AC14: 35
C15: Total | D15: =SUM(D12:D14) -> 2947 | E15: =SUM(E12:E14) -> 318 | F15: =E15/D15 -> 0.10790635 | G15: =SUM(G12:G14) -> 2629 | H15: =SUM(H12:H14) -> 0 | I15: =SUM(I12:I14) -> 15 | J15: =SUM(J12:J14) -> 0 | K15: =SUM(K12:K14) -> 0 | L15: =SUM(L12:L14) -> 0 | M15: =SUM(M12:M14) -> 53 | N15: =SUM(N12:N14) -> 0 | ... P15: =SUM(P12:P14) -> 76 | V15: SEPTEMBER | W15: 53 | X15: 0 | Y15: 1930 | Z15: 270 | AA15: =Y15-Z15 -> 1660 | AB15: =Z15/Y15 -> 0.13989637 | AC15: 1
C16: Grand Total | D16: =D10+D15 -> 4144 | E16: =E10+E15 -> 1098 | F16: =E16/D16 -> 0.26496139 | G16: =G10+G15 -> 3046 | H16: =H10+H15 -> 0 | I16: =I10+I15 -> 16 | J16: =J10+J15 -> 0 | K16: =K10+K15 -> 0 | L16: =L10+L15 -> 23 | M16: =M10+M15 -> 57 | N16: =N10+N15 -> 19 | ... P16: =P10+P15 -> 131 | V16: OCTOBER | W16: 7 | X16: 0 | Y16: 1183 | Z16: 2 | AA16: =Y16-Z16 -> 1181 | AB16: =Z16/Y16 -> 0.0016906171 | AC16: 0
C17: *Note: This report was generated based on Hexagon data as of- July 3 2026 at 7.00 AM | V17: Grand Total | W17: 248 | X17: 0 | Y17: 12763 | Z17: 1501 | AA17: =Y17-Z17 -> 11262 | AB17: =Z17/Y17 -> 0.11760558 | AC17: 98
D28: =13849-13905 -> -56

Sheet DETAILED ITR LIST
A1: Task ID | B1: Asset - Tag | C1: Asset Pack ID | D1: Cable Pack ID | E1: Pipe Pack ID | F1: Loop Name | G1: Description | H1: Category (Summary) | I1: Discipline | J1: Task Type (Name) | K1: Discipline (Summary) | L1: Asset - Description | M1: Systemization - Process Plant ID | N1: Responsible Company (Summary) | O1: Actual Duration | P1: Scheduled Duration | Q1: Task Duration | R1: Title - Actual MH/Person | S1: Title - Planned MH/Person | T1: Field005 (Custom) | U1: Physical Location - Area (Summary) | V1: Systemization - Subsystem (Summary) | W1: Closing Date | X1: Subsystem ID | Y1: Priority | Z1: Priority | AA1: Test Form - Description | AB1: Asset Discipline | AC1: Task State | AD1: Priority | AE1: RFC
A2: T-00018-0192 | B2: PS5-61-IU-0001A | G2: CPX02 - Power transformer | H2: PCOM - Precommissioning | I2: E | J2: Conformity Check | K2: E - Electrical | L2: 11/33kV Transformer - 6.8 MVA | M2: EACOP | N2: CPP AGI | Q2: 16 | U2: PS5 - TZA - PS5 - Tanzania | V2: PS5-60-01 - Power Generation Package A | X2: PS5-60-01 | AA2: Power Transformer | AB2: E | AC2: To be completed | AD2: PS5 - Milestone B
A3: T-00018-0193 | B3: PS5-61-IU-0001B | G3: CPX02 - Power transformer | H3: PCOM - Precommissioning | I3: E | J3: Conformity Check | K3: E - Electrical | L3: 11/33kV Transformer - 6.8 MVA | M3: EACOP | N3: CPP AGI | Q3: 16 | U3: PS5 - TZA - PS5 - Tanzania | V3: PS5-60-04 - Power Generation Package B | X3: PS5-60-04 | AA3: Power Transformer | AB3: E | AC3: To be completed | AD3: PS5 - Milestone B
A4: T-00018-0194 | B4: PS5-61-IU-0001C | G4: CPX02 - Power transformer | H4: PCOM - Precommissioning | I4: E | J4: Conformity Check | K4: E - Electrical | L4: 11/33kV Transformer - 6.8 MVA | M4: EACOP | N4: CPP AGI | Q4: 16 | U4: PS5 - TZA - PS5 - Tanzania | V4: PS5-60-07 - Power Generation Package C | X4: PS5-60-07 | AA4: Power Transformer | AB4: E | AC4: To be completed | AD4: PS5 - Milestone D
A5: T-00018-0195 | B5: PS5-61-IU-0001D | G5: CPX02 - Power transformer | H5: PCOM - Precommissioning | I5: E | J5: Conformity Check | K5: E - Electrical | L5: 11/33kV Transformer - 6.8 MVA | M5: EACOP | N5: CPP AGI | Q5: 16 | U5: PS5 - TZA - PS5 - Tanzania | V5: PS5-60-10 - Power Generation Package D | X5: PS5-60-10 | AA5: Power Transformer | AB5: E | AC5: To be completed | AD5: PS5 - Milestone D
A6: T-00018-0196 | B6: PS5-61-IU-0001E | G6: CPX02 - Power transformer | H6: PCOM - Precommissioning | I6: E | J6: Conformity Check | K6: E - Electrical | L6: 11/33kV Transformer - 6.8 MVA | M6: EACOP | N6: CPP AGI | Q6: 16 | U6: PS5 - TZA - PS5 - Tanzania | V6: PS5-60-13 - Power Generation Package E | X6: PS5-60-13 | AA6: Power Transformer | AB6: E | AC6: To be completed | AD6: PS5 - Milestone D
A7: T-00018-0197 | B7: PS5-61-IU-0001F | G7: CPX02 - Power transformer | H7: PCOM - Precommissioning | I7: E | J7: Conformity Check | K7: E - Electrical | L7: 11/33kV Transformer - 6.8 MVA | M7: EACOP | N7: CPP AGI | Q7: 16 | U7: PS5 - TZA - PS5 - Tanzania | V7: PS5-60-16 - Power Generation Package F | X7: PS5-60-16 | AA7: Power Transformer | AB7: E | AC7: To be completed | AD7: PS5 - Milestone D
A8: T-00018-0198 | B8: PS5-61-IU-0001G | G8: CPX02 - Power transformer | H8: PCOM - Precommissioning | I8: E | J8: Conformity Check | K8: E - Electrical | L8: 11/33kV Transformer - 6.8 MVA | M8: EACOP | N8: CPP AGI | Q8: 16 | U8: PS5 - TZA - PS5 - Tanzania | V8: PS5-60-19 - Power Generation Package G | X8: PS5-60-19 | AA8: Power Transformer | AB8: E | AC8: To be completed | AD8: PS5 - Milestone E
A9: T-00022-3334 | B9: PS5-60-IJ-0001A-CH04 | G9: CPX08 - HV Power Cable | H9: PCOM - Precommissioning | I9: E | J9: Conformity Check | K9: E - Electrical | L9: Cable FROM PS5-60-GE-8100A TO PS5-60-IJ-0001A | M9: EACOP | N9: CPP AGI | Q9: 4 | T9: TZ-MID-68-WPR2-150101 | U9: PS5 - TZA - PS5 - Tanzania | V9: PS5-60-01 - Power Generation Package A | W9: 46088.478 | X9: PS5-60-01 | AA9: HV Power Cable | AB9: E | AC9: Closed | AD9: PS5 - Milestone B
A10: T-00022-3335 | B10: PS5-60-IJ-0001B-CH04 | G10: CPX08 - HV Power Cable | H10: PCOM - Precommissioning | I10: E | J10: Conformity Check | K10: E - Electrical | L10: Cable FROM PS5-60-GE-8100B TO PS5-60-IJ-0001B | M10: EACOP | N10: CPP AGI | Q10: 4 | T10: TZ-MID-68-WPR2-150101 | U10: PS5 - TZA - PS5 - Tanzania | V10: PS5-60-04 - Power Generation Package B | W10: 46088.483 | X10: PS5-60-04 | AA10: HV Power Cable | AB10: E | AC10: Closed | AD10: PS5 - Milestone B
A11: T-00022-3336 | B11: PS5-60-IJ-0001C-CH04 | G11: CPX08 - HV Power Cable | H11: PCOM - Precommissioning | I11: E | J11: Conformity Check | K11: E - Electrical | L11: Cable FROM PS5-60-GE-8100C TO PS5-60-IJ-0001C | M11: EACOP | N11: CPP AGI | Q11: 4 | T11: TZ-MID-68-WPR2-150101 | U11: PS5 - TZA - PS5 - Tanzania | V11: PS5-60-07 - Power Generation Package C | W11: 46088.485 | X11: PS5-60-07 | AA11: HV Power Cable | AB11: E | AC11: Closed | AD11: PS5 - Milestone D
A12: T-00022-3337 | B12: PS5-60-IJ-0001D-CH04 | G12: CPX08 - HV Power Cable | H12: PCOM - Precommissioning | I12: E | J12: Conformity Check | K12: E - Electrical | L12: Cable FROM PS5-60-GE-8100D TO PS5-60-IJ-0001D | M12: EACOP | N12: CPP AGI | Q12: 4 | T12: TZ-MID-68-WPR2-150101 | U12: PS5 - TZA - PS5 - Tanzania | V12: PS5-60-10 - Power Generation Package D | W12: 46088.488 | X12: PS5-60-10 | AA12: HV Power Cable | AB12: E | AC12: Closed | AD12: PS5 - Milestone D
A13: T-00022-3338 | B13: PS5-60-IJ-0001E-CH04 | G13: CPX08 - HV Power Cable | H13: PCOM - Precommissioning | I13: E | J13: Conformity Check | K13: E - Electrical | L13: Cable FROM PS5-60-GE-8100E TO PS5-60-IJ-0001E | M13: EACOP | N13: CPP AGI | Q13: 4 | T13: TZ-MID-68-WPR2-150101 | U13: PS5 - TZA - PS5 - Tanzania | V13: PS5-60-13 - Power Generation Package E | W13: 46088.49 | X13: PS5-60-13 | AA13: HV Power Cable | AB13: E | AC13: Closed | AD13: PS5 - Milestone D
A14: T-00022-3339 | B14: PS5-60-IJ-0001F-CH04 | G14: CPX08 - HV Power Cable | H14: PCOM - Precommissioning | I14: E | J14: Conformity Check | K14: E - Electrical | L14: Cable FROM PS5-60-GE-8100F TO PS5-60-IJ-0001F | M14: EACOP | N14: CPP AGI | Q14: 4 | T14: TZ-MID-68-WPR2-150101 | U14: PS5 - TZA - PS5 - Tanzania | V14: PS5-60-16 - Power Generation Package F | W14: 46088.492 | X14: PS5-60-16 | AA14: HV Power Cable | AB14: E | AC14: Closed | AD14: PS5 - Milestone D
A15: T-00022-3340 | B15: PS5-60-IJ-0001G-CH04 | G15: CPX08 - HV Power Cable | H15: PCOM - Precommissioning | I15: E | J15: Conformity Check | K15: E - Electrical | L15: Cable FROM PS5-60-GE-8100G TO PS5-60-IJ-0001G | M15: EACOP | N15: CPP AGI | Q15: 4 | T15: TZ-MID-68-WPR2-150101 | U15: PS5 - TZA - PS5 - Tanzania | V15: PS5-60-19 - Power Generation Package G | W15: 46088.494 | X15: PS5-60-19 | AA15: HV Power Cable | AB15: E | AC15: Closed | AD15: PS5 - Milestone E
A16: T-00022-3377 | B16: PS5-61-IJ-0001-CH01 | G16: CPX08 - HV Power Cable | H16: PCOM - Precommissioning | I16: E | J16: Conformity Check | K16: E - Electrical | L16: Cable FROM PS5-61-IU-0001A TO PS5-61-IJ-0001 | M16: EACOP | N16: CPP AGI | Q16: 4 | T16: TZ-MID-68-WPR2-150101 | U16: PS5 - TZA - PS5 - Tanzania | V16: PS5-60-01 - Power Generation Package A | W16: 46136.342 | X16: PS5-60-01 | AA16: HV Power Cable | AB16: E | AC16: Closed | AD16: PS5 - Milestone B
A17: T-00022-3378 | B17: PS5-61-IJ-0001-CH02 | G17: CPX08 - HV Power Cable | H17: PCOM - Precommissioning | I17: E | J17: Conformity Check | K17: E - Electrical | L17: Cable FROM PS5-61-IU-0001A TO PS5-61-IJ-0001 | M17: EACOP | N17: CPP AGI | Q17: 4 | T17: TZ-MID-68-WPR2-150101 | U17: PS5 - TZA - PS5 - Tanzania | V17: PS5-60-01 - Power Generation Package A | W17: 46136.541 | X17: PS5-60-01 | AA17: HV Power Cable | AB17: E | AC17: Closed | AD17: PS5 - Milestone B
A18: T-00022-3379 | B18: PS5-61-IJ-0001-CH03 | G18: CPX08 - HV Power Cable | H18: PCOM - Precommissioning | I18: E | J18: Conformity Check | K18: E - Electrical | L18: Cable FROM PS5-61-IU-0001A TO PS5-61-IJ-0001 | M18: EACOP | N18: CPP AGI | Q18: 4 | T18: TZ-MID-68-WPR2-150101 | U18: PS5 - TZA - PS5 - Tanzania | V18: PS5-60-01 - Power Generation Package A | W18: 46136.542 | X18: PS5-60-01 | AA18: HV Power Cable | AB18: E | AC18: Closed | AD18: PS5 - Milestone B
A19: T-00022-3380 | B19: PS5-61-IJ-0001-CH04 | G19: CPX08 - HV Power Cable | H19: PCOM - Precommissioning | I19: E | J19: Conformity Check | K19: E - Electrical | L19: Cable FROM PS5-61-IU-0001B TO PS5-61-IJ-0001 | M19: EACOP | N19: CPP AGI | Q19: 4 | T19: TZ-MID-68-WPR2-150101 | U19: PS5 - TZA - PS5 - Tanzania | V19: PS5-60-04 - Power Generation Package B | W19: 46136.542 | X19: PS5-60-04 | AA19: HV Power Cable | AB19: E | AC19: Closed | AD19: PS5 - Milestone B
A20: T-00022-3381 | B20: PS5-61-IJ-0001-CH05 | G20: CPX08 - HV Power Cable | H20: PCOM - Precommissioning | I20: E | J20: Conformity Check | K20: E - Electrical | L20: Cable FROM PS5-61-IU-0001B TO PS5-61-IJ-0001 | M20: EACOP | N20: CPP AGI | Q20: 4 | T20: TZ-MID-68-WPR2-150101 | U20: PS5 - TZA - PS5 - Tanzania | V20: PS5-60-04 - Power Generation Package B | W20: 46136.542 | X20: PS5-60-04 | AA20: HV Power Cable | AB20: E | AC20: Closed | AD20: PS5 - Milestone B
... A57: T-00022-3430 | B57: PS5-61-IU-0001G-CH03 | G57: CPX08 - HV Power Cable | H57: PCOM - Precommissioning | I57: E | J57: Conformity Check | K57: E - Electrical | L57: Cable FROM PS5-60-GE-8100G TO PS5-61-IU-0001G | M57: EACOP | N57: CPP AGI | Q57: 4 | T57: TZ-MID-68-WPR2-150101 | U57: PS5 - TZA - PS5 - Tanzania | V57: PS5-60-19 - Power Generation Package G | W57: 46075.472 | X57: PS5-60-19 | AA57: HV Power Cable | AB57: E | AC57: Closed | AD57: PS5 - Milestone E
A58: T-00023-10536 | B58: PS5-60-IN-0002A-CG01 | G58: CPX09 - LV Power Cable | H58: PCOM - Precommissioning | I58: E | J58: Conformity Check | K58: E - Electrical | L58: Cable FROM PS5-60-IH-0001A TO PS5-60-IN-0002A | M58: EACOP | N58: CPP AGI | Q58: 1 | S58: 1 | U58: PS5 - TZA - PS5 - Tanzania | V58: PS5-60-57 - Fuel Conditioning Module PS5-60-UZ-8900A (UCP) | X58: PS5-60-57 | AA58: LV Power Cable | AB58: E | AC58: To be completed | AD58: PS5 - Milestone B
A59: T-00023-10537 | B59: PS5-60-IN-0002B-CG01 | G59: CPX09 - LV Power Cable | H59: PCOM - Precommissioning | I59: E | J59: Conformity Check | K59: E - Electrical | L59: Cable FROM PS5-60-IH-0001B TO PS5-60-IN-0002B | M59: EACOP | N59: CPP AGI | Q59: 1 | S59: 1 | U59: PS5 - TZA - PS5 - Tanzania | V59: PS5-60-59 - Fuel Conditioning Module PS5-60-UZ-8900B (UCP) | X59: PS5-60-59 | AA59: LV Power Cable | AB59: E | AC59: To be completed | AD59: PS5 - Milestone B
A60: T-00023-10538 | B60: PS5-60-IN-0002C-CG01 | G60: CPX09 - LV Power Cable | H60: PCOM - Precommissioning | I60: E | J60: Conformity Check | K60: E - Electrical | L60: Cable FROM PS5-60-IH-0001C TO PS5-60-IN-0002C | M60: EACOP | N60: CPP AGI | Q60: 1 | S60: 1 | U60: PS5 - TZA - PS5 - Tanzania | V60: PS5-60-61 - Fuel Conditioning Module PS5-60-UZ-8900C (UCP) | X60: PS5-60-61 | AA60: LV Power Cable | AB60: E | AC60: To be completed | AD60: PS5 - Milestone D
A61: T-00023-10539 | B61: PS5-60-IN-0002D-CG01 | G61: CPX09 - LV Power Cable | H61: PCOM - Precommissioning | I61: E | J61: Conformity Check | K61: E - Electrical | L61: Cable FROM PS5-60-IH-0001D TO PS5-60-IN-0002D | M61: EACOP | N61: CPP AGI | Q61: 1 | S61: 1 | U61: PS5 - TZA - PS5 - Tanzania | V61: PS5-60-63 - Fuel Conditioning Module PS5-60-UZ-8900D (UCP) | X61: PS5-60-63 | AA61: LV Power Cable | AB61: E | AC61: To be completed | AD61: PS5 - Milestone D
A62: T-00023-10540 | B62: PS5-60-IN-0002E-CG01 | G62: CPX09 - LV Power Cable | H62: PCOM - Precommissioning | I62: E | J62: Conformity Check | K62: E - Electrical | L62: Cable FROM PS5-60-IH-0001E TO PS5-60-IN-0002E | M62: EACOP | N62: CPP AGI | Q62: 1 | S62: 1 | U62: PS5 - TZA - PS5 - Tanzania | V62: PS5-60-65 - Fuel Conditioning Module PS5-60-UZ-8900E (UCP) | X62: PS5-60-65 | AA62: LV Power Cable | AB62: E | AC62: To be completed | AD62: PS5 - Milestone D
A63: T-00023-10541 | B63: PS5-60-IN-0002F-CG01 | G63: CPX09 - LV Power Cable | H63: PCOM - Precommissioning | I63: E | J63: Conformity Check | K63: E - Electrical | L63: Cable FROM PS5-60-IH-0001F TO PS5-60-IN-0002F | M63: EACOP | N63: CPP AGI | Q63: 1 | S63: 1 | U63: PS5 - TZA - PS5 - Tanzania | V63: PS5-60-67 - Fuel Conditioning Module PS5-60-UZ-8900F (UCP) | X63: PS5-60-67 | AA63: LV Power Cable | AB63: E | AC63: To be completed | AD63: PS5 - Milestone D
A64: T-00023-10542 | B64: PS5-60-IN-0002G-CG01 | G64: CPX09 - LV Power Cable | H64: PCOM - Precommissioning | I64: E | J64: Conformity Check | K64: E - Electrical | L64: Cable FROM PS5-60-IH-0001G TO PS5-60-IN-0002G | M64: EACOP | N64: CPP AGI | Q64: 1 | S64: 1 | U64: PS5 - TZA - PS5 - Tanzania | V64: PS5-60-69 - Fuel Conditioning Module PS5-60-UZ-8900G (UCP) | X64: PS5-60-69 | AA64: LV Power Cable | AB64: E | AC64: To be completed | AD64: PS5 - Milestone E
A65: T-00023-10593 | B65: PS5-60-IH-0001A-CG01 | G65: CPX09 - LV Power Cable | H65: PCOM - Precommissioning | I65: E | J65: Conformity Check | K65: E - Electrical | L65: Cable FROM PS5-61-IK-0003 TO PS5-60-IH-0001A | M65: EACOP | N65: CPP AGI | Q65: 1 | S65: 1 | U65: PS5 - TZA - PS5 - Tanzania | V65: PS5-60-03 - Power Gen Package A Generator Auxiliary MCCs & DBs | X65: PS5-60-03 | AA65: LV Power Cable | AB65: E | AC65: To be completed | AD65: PS5 - Milestone B
A66: T-00023-10594 | B66: PS5-60-IH-0001B-CG01 | G66: CPX09 - LV Power Cable | H66: PCOM - Precommissioning | I66: E | J66: Conformity Check | K66: E - Electrical | L66: Cable FROM PS5-61-IK-0003 TO PS5-60-IH-0001B | M66: EACOP | N66: CPP AGI | Q66: 1 | S66: 1 | U66: PS5 - TZA - PS5 - Tanzania | V66: PS5-60-06 - Power Gen Package B Generator Auxiliary MCCs & DBs | X66: PS5-60-06 | AA66: LV Power Cable | AB66: E | AC66: To be completed | AD66: PS5 - Milestone B
A67: T-00023-10595 | B67: PS5-60-IH-0001C-CG01 | G67: CPX09 - LV Power Cable | H67: PCOM - Precommissioning | I67: E | J67: Conformity Check | K67: E - Electrical | L67: Cable FROM PS5-61-IK-0003 TO PS5-60-IH-0001C | M67: EACOP | N67: CPP AGI | Q67: 1 | S67: 1 | U67: PS5 - TZA - PS5 - Tanzania | V67: PS5-60-09 - Power Gen Package C Generator Auxiliary MCCs & DBs | X67: PS5-60-09 | AA67: LV Power Cable | AB67: E | AC67: To be completed | AD67: PS5 - Milestone D
A68: T-00023-10596 | B68: PS5-60-IH-0001D-CG01 | G68: CPX09 - LV Power Cable | H68: PCOM - Precommissioning | I68: E | J68: Conformity Check | K68: E - Electrical | L68: Cable FROM PS5-61-IK-0003 TO PS5-60-IH-0001D | M68: EACOP | N68: CPP AGI | Q68: 1 | S68: 1 | U68: PS5 - TZA - PS5 - Tanzania | V68: PS5-60-12 - Power Gen Package D Generator Auxiliary MCCs & DBs | X68: PS5-60-12 | AA68: LV Power Cable | AB68: E | AC68: To be completed | AD68: PS5 - Milestone D
A69: T-00023-10597 | B69: PS5-60-IH-0001E-CG01 | G69: CPX09 - LV Power Cable | H69: PCOM - Precommissioning | I69: E | J69: Conformity Check | K69: E - Electrical | L69: Cable FROM PS5-61-IK-0003 TO PS5-60-IH-0001E | M69: EACOP | N69: CPP AGI | Q69: 1 | S69: 1 | U69: PS5 - TZA - PS5 - Tanzania | V69: PS5-60-15 - Power Gen Package E Generator Auxiliary MCCs & DBs | X69: PS5-60-15 | AA69: LV Power Cable | AB69: E | AC69: To be completed | AD69: PS5 - Milestone D
... A91: T-00023-10904 | B91: PS5-60-ISO-62800G-CL01 | G91: CPX09 - LV Power Cable | H91: PCOM - Precommissioning | I91: E | J91: Conformity Check | K91: E - Electrical | L91: Cable FROM PS5-60-IH-0001G TO PS5-60-ISO-62800G | M91: EACOP | N91: CPP AGI | Q91: 1 | S91: 1 | U91: PS5 - TZA - PS5 - Tanzania | V91: PS5-60-21 - Power Gen Package G Generator Auxiliary MCCs & DBs | X91: PS5-60-21 | AA91: LV Power Cable | AB91: E | AC91: To be completed | AD91: PS5 - Milestone E
A92: T-00023-4725 | B92: PS5-03-SEA-0003-CL01 | G92: CPX09 - LV Power Cable | H92: PCOM - Precommissioning | I92: E | J92: Conformity Check | K92: E - Electrical | L92: Cable FROM PS5-06-IG-0004A TO PS5-03-SEA-0003 | M92: EACOP | N92: CPP AGI | Q92: 1 | T92: TZ-MID-68-WPR2-150101 | U92: PS5 - TZA - PS5 - Tanzania | V92: PS5-03-14 - FZ-14 - Power Generation Building - Switchgear Room | X92: PS5-03-14 | AA92: LV Power Cable | AB92: E | AC92: To be completed | AD92: PS5 - Milestone E
A93: T-00023-4978 | B93: PS5-60-BE-0001-CL01 | G93: CPX09 - LV Power Cable | H93: PCOM - Precommissioning | I93: E | J93: Conformity Check | K93: E - Electrical | L93: Cable FROM PS5-60-IH-0002 TO PS5-60-BE-0001 | M93: EACOP | N93: CPP AGI | Q93: 1 | T93: TZ-MID-68-WPR2-150101 | U93: PS5 - TZA - PS5 - Tanzania | V93: PS5-60-27 - Compressed Air Starting Skid | X93: PS5-60-27 | AA93: LV Power Cable | AB93: E | AC93: To be completed | AD93: PS5 - Milestone B
A94: T-00023-4979 | B94: PS5-60-BE-0001-CL02 | G94: CPX09 - LV Power Cable | H94: PCOM - Precommissioning | I94: E | J94: Conformity Check | K94: E - Electrical | L94: Cable FROM PS5-60-IH-0002 TO PS5-60-BE-0001 | M94: EACOP | N94: CPP AGI | Q94: 1 | T94: TZ-MID-68-WPR2-150101 | U94: PS5 - TZA - PS5 - Tanzania | V94: PS5-60-27 - Compressed Air Starting Skid | X94: PS5-60-27 | AA94: LV Power Cable | AB94: E | AC94: To be completed | AD94: PS5 - Milestone B
A95: T-00023-4981 | B95: PS5-60-BE-0001-CL04 | G95: CPX09 - LV Power Cable | H95: PCOM - Precommissioning | I95: E | J95: Conformity Check | K95: E - Electrical | L95: Cable FROM PS5-06-IG-0004B TO PS5-60-BE-0001 | M95: EACOP | N95: CPP AGI | Q95: 1 | T95: TZ-MID-68-WPR2-150101 | U95: PS5 - TZA - PS5 - Tanzania | V95: PS5-60-27 - Compressed Air Starting Skid | X95: PS5-60-27 | AA95: LV Power Cable | AB95: E | AC95: To be completed | AD95: PS5 - Milestone B
A96: T-00023-4982 | B96: PS5-60-BE-0002-CL01 | G96: CPX09 - LV Power Cable | H96: PCOM - Precommissioning | I96: E | J96: Conformity Check | K96: E - Electrical | L96: Cable FROM PS5-60-IH-0002 TO PS5-60-BE-0002 | M96: EACOP | N96: CPP AGI | Q96: 1 | T96: TZ-MID-68-WPR2-150101 | U96: PS5 - TZA - PS5 - Tanzania | V96: PS5-60-26 - Instrument Air Compressor Skid | X96: PS5-60-26 | AA96: LV Power Cable | AB96: E | AC96: To be completed | AD96: PS5 - Milestone B
A97: T-00023-4983 | B97: PS5-60-BE-0002-CL02 | G97: CPX09 - LV Power Cable | H97: PCOM - Precommissioning | I97: E | J97: Conformity Check | K97: E - Electrical | L97: Cable FROM PS5-60-IH-0002 TO PS5-60-BE-0002 | M97: EACOP | N97: CPP AGI | Q97: 1 | T97: TZ-MID-68-WPR2-150101 | U97: PS5 - TZA - PS5 - Tanzania | V97: PS5-60-26 - Instrument Air Compressor Skid | X97: PS5-60-26 | AA97: LV Power Cable | AB97: E | AC97: To be completed | AD97: PS5 - Milestone B
...

Sheet PRELIMINARY -MILESTONES
A1: SUBSYSTEM | B1: SUBSYTEM DESCRIPTIONS | C1: Priority | D1: REMARKS
A2: PS5-60-22 | B2: PS5-60-22 - Power Gen Master UCP | C2: PS5 - Milestone B
A3: PS5-60-26 | B3: PS5-60-26 - Instrument Air Compressor Skid | C3: PS5 - Milestone B
A4: PS5-60-27 | B4: PS5-60-27 - Compressed Air Starting Skid | C4: PS5 - Milestone B
A5: PS5-60-02 | B5: PS5-60-02 - Power Gen Package A (UCP) | C5: PS5 - Milestone B
A6: PS5-60-03 | B6: PS5-60-03 - Power Gen Package A Generator Auxiliary MCCs & DBs | C6: PS5 - Milestone B
A7: PS5-71-23 | B7: PS5-71-23 - Diesel Fuel Pre Pressure Module (UCP) | C7: PS5 - Milestone B
A8: PS5-60-70 | B8: PS5-60-70 - Engine A Cooling system | C8: PS5 - Milestone B
A9: PS5-60-57 | B9: PS5-60-57 - Fuel Conditioning Module PS5-60-UZ-8900A (UCP) | C9: PS5 - Milestone B
A10: PS5-60-05 | B10: PS5-60-05 - Power Gen Package B (UCP) | C10: PS5 - Milestone B
A11: PS5-60-06 | B11: PS5-60-06 - Power Gen Package B Generator Auxiliary MCCs & DBs | C11: PS5 - Milestone B
A12: PS5-60-35 | B12: PS5-60-35 - Injector Tip Cooling Module A | C12: PS5 - Milestone B
A13: PS5-60-42 | B13: PS5-60-42 - Oil Mist Separator Skid PS5-60-VS-9100A | C13: PS5 - Milestone B
... A73: PS5-71-09 | B73: PS5-71-09 - CFO Pre-Pressure Modules (UCP) | C73: PS5 - Milestone H

Sheet MILESTONE & DIS.
B3: Responsible Company : CPP AGI-VENDOR-MANTRAC CHECKLIST SUMMERY
B4: Milestone & Discipline | C4: Subsystem Total | D4: ITR Total | E4: ITR EACOP Approved | F4: ITR Open | H4: CUT OFF DATE-19-JUNE-2026
H5: 27 June | I5: 28 June | J5: 29 June | K5: 30 June | L5: 1 July | M5: 2 July | N5: 3 July | O5: TOTAL
B6: PS5 - Milestone B | C6: 23 | D6: =COUNTIFS('DETAILED ITR LIST'!AD:AD,"PS5 - Milestone B") -> 1298 | E6: =COUNTIFS('DETAILED ITR LIST'!AD:AD,"PS5 - Milestone B",'DETAILED ITR LIST'!AC:AC,"Closed") -> 429 | F6: =D6-E6 -> 869 | O6: =E6/D6 -> 0.33050847
B7: E - Electrical | D7: =COUNTIFS('DETAILED ITR LIST'!AD:AD,"PS5 - Milestone B",'DETAILED ITR LIST'!K:K,"E - Electrical") -> 470 | E7: =COUNTIFS('DETAILED ITR LIST'!AD:AD,"PS5 - Milestone B",'DETAILED ITR LIST'!K:K,"E - Electrical",'DETAILED ITR LIST'!AC:AC,"CLOSED") -> 176 | F7: =D7-E7 -> 294 | H7: 15 | L7: 31 | O7: =SUM(H7:N7) -> 46 | R7: MILESTONES-CPP AGI STATUS
B8: I - Instrumentation | D8: =COUNTIFS('DETAILED ITR LIST'!AD:AD,"PS5 - Milestone B",'DETAILED ITR LIST'!K:K,"I - Instrumentation") -> 421 | E8: =COUNTIFS('DETAILED ITR LIST'!AD:AD,"PS5 - Milestone B",'DETAILED ITR LIST'!K:K,"I - Instrumentation",'DETAILED ITR LIST'!AC:AC,"CLOSED") -> 4 | F8: =D8-E8 -> 417 | L8: 4 | O8: =SUM(H8:N8) -> 4 | R8: MILESTONES | S8: TOTAL ITRs | T8: CLOSED | U8: REMAIINING | V8: % | W8: CUT OFF-19-JUNE
B9: M - Mechanical | D9: =COUNTIFS('DETAILED ITR LIST'!AD:AD,"PS5 - Milestone B",'DETAILED ITR LIST'!K:K,"M - Mechanical") -> 58 | E9: =COUNTIFS('DETAILED ITR LIST'!AD:AD,"PS5 - Milestone B",'DETAILED ITR LIST'!K:K,"M - Mechanical",'DETAILED ITR LIST'!AC:AC,"CLOSED") -> 58 | F9: =D9-E9 -> 0 | K9: 4 | O9: =SUM(H9:N9) -> 4 | R9: PS5 - Milestone B | S9: =COUNTIFS('DETAILED ITR LIST'!AD:AD,"PS5 - Milestone B") -> 1298 | T9: =COUNTIFS('DETAILED ITR LIST'!AD:AD,"PS5 - Milestone B",'DETAILED ITR LIST'!AC:AC,"Closed") -> 429 | U9: =S9-T9 -> 869 | V9: =T9/S9 -> 0.33050847 | W9: =SUM(O7:O11) -> 59
B10: P - Piping & Vessel | D10: =COUNTIFS('DETAILED ITR LIST'!AD:AD,"PS5 - Milestone B",'DETAILED ITR LIST'!K:K,"P - Piping & Vessel") -> 315 | E10: =COUNTIFS('DETAILED ITR LIST'!AD:AD,"PS5 - Milestone B",'DETAILED ITR LIST'!K:K,"P - Piping & Vessel",'DETAILED ITR LIST'!AC:AC,"CLOSED") -> 191 | F10: =D10-E10 -> 124 | H10: 1 | M10: 4 | O10: =SUM(H10:N10) -> 5 | R10: PS5 - Milestone D | S10: =COUNTIFS('DETAILED ITR LIST'!AD:AD,"PS5 - Milestone D") -> 2103 | T10: =COUNTIFS('DETAILED ITR LIST'!AD:AD,"PS5 - Milestone D",'DETAILED ITR LIST'!AC:AC,"Closed") -> 518 | U10: =S10-T10 -> 1585 | V10: =T10/S10 -> 0.24631479 | W10: =SUM(O13:O17) -> 45
B11: T - Telecom | D11: =COUNTIFS('DETAILED ITR LIST'!AD:AD,"PS5 - Milestone B",'DETAILED ITR LIST'!K:K,"T - Telecom") -> 34 | E11: =COUNTIFS('DETAILED ITR LIST'!AD:AD,"PS5 - Milestone B",'DETAILED ITR LIST'!K:K,"T - Telecom",'DETAILED ITR LIST'!AC:AC,"CLOSED") -> 0 | F11: =D11-E11 -> 34 | O11: =SUM(H11:N11) -> 0 | R11: PS5 - Milestone E | S11: =COUNTIFS('DETAILED ITR LIST'!AD:AD,"PS5 - Milestone E") -> 589 | T11: =COUNTIFS('DETAILED ITR LIST'!AD:AD,"PS5 - Milestone E",'DETAILED ITR LIST'!AC:AC,"Closed") -> 117 | U11: =S11-T11 -> 472 | V11: =T11/S11 -> 0.19864177 | W11: =SUM(O19:O23) -> 22
B12: PS5 - Milestone D | C12: 36 | D12: =COUNTIFS('DETAILED ITR LIST'!AD:AD,"PS5 - Milestone D") -> 2103 | E12: =COUNTIFS('DETAILED ITR LIST'!AD:AD,"PS5 - Milestone D",'DETAILED ITR LIST'!AC:AC,"Closed") -> 518 | F12: =D12-E12 -> 1585 | O12: =E12/D12 -> 0.24631479 | R12: PS5 - Milestone H | S12: =COUNTIFS('DETAILED ITR LIST'!AD:AD,"PS5 - Milestone H") -> 154 | T12: =COUNTIFS('DETAILED ITR LIST'!AD:AD,"PS5 - Milestone H",'DETAILED ITR LIST'!AC:AC,"Closed") -> 34 | U12: =S12-T12 -> 120 | V12: =T12/S12 -> 0.22077922 | W12: =SUM(O25:O29) -> 5
B13: E - Electrical | D13: =COUNTIFS('DETAILED ITR LIST'!AD:AD,"PS5 - Milestone D",'DETAILED ITR LIST'!K:K,"E - Electrical") -> 752 | E13: =COUNTIFS('DETAILED ITR LIST'!AD:AD,"PS5 - Milestone D",'DETAILED ITR LIST'!K:K,"E - Electrical",'DETAILED ITR LIST'!AC:AC,"CLOSED") -> 99 | F13: =D13-E13 -> 653 | L13: 3 | N13: 5 | O13: =SUM(H13:N13) -> 8 | R13: TOTAL | S13: =SUM(S9:S12) -> 4144 | T13: =SUM(T9:T12) -> 1098 | U13: =S13-T13 -> 3046 | V13: =T13/S13 -> 0.26496139 | W13: =SUM(W9:W12) -> 131
B14: I - Instrumentation | D14: =COUNTIFS('DETAILED ITR LIST'!AD:AD,"PS5 - Milestone D",'DETAILED ITR LIST'!K:K,"I - Instrumentation") -> 646 | E14: =COUNTIFS('DETAILED ITR LIST'!AD:AD,"PS5 - Milestone D",'DETAILED ITR LIST'!K:K,"I - Instrumentation",'DETAILED ITR LIST'!AC:AC,"CLOSED") -> 11 | F14: =D14-E14 -> 635 | L14: 11 | O14: =SUM(H14:N14) -> 11
B15: M - Mechanical | D15: =COUNTIFS('DETAILED ITR LIST'!AD:AD,"PS5 - Milestone D",'DETAILED ITR LIST'!K:K,"M - Mechanical") -> 109 | E15: =COUNTIFS('DETAILED ITR LIST'!AD:AD,"PS5 - Milestone D",'DETAILED ITR LIST'!K:K,"M - Mechanical",'DETAILED ITR LIST'!AC:AC,"CLOSED") -> 109 | F15: =D15-E15 -> 0 | K15: 8 | O15: =SUM(H15:N15) -> 8 | R15: HYDROTEST-ITRs STATUS
B16: P - Piping & Vessel | D16: =COUNTIFS('DETAILED ITR LIST'!AD:AD,"PS5 - Milestone D",'DETAILED ITR LIST'!K:K,"P - Piping & Vessel") -> 516 | E16: =COUNTIFS('DETAILED ITR LIST'!AD:AD,"PS5 - Milestone D",'DETAILED ITR LIST'!K:K,"P - Piping & Vessel",'DETAILED ITR LIST'!AC:AC,"CLOSED") -> 299 | F16: =D16-E16 -> 217 | K16: 6 | L16: 1 | M16: 8 | N16: 3 | O16: =SUM(H16:N16) -> 18 | R16: MILESTONES | S16: TOTAL ITRs | T16: CLOSED | U16: REMAIINING | V16: %
B17: T - Telecom | D17: =COUNTIFS('DETAILED ITR LIST'!AD:AD,"PS5 - Milestone D",'DETAILED ITR LIST'!K:K,"T - Telecom") -> 80 | E17: =COUNTIFS('DETAILED ITR LIST'!AD:AD,"PS5 - Milestone D",'DETAILED ITR LIST'!K:K,"T - Telecom",'DETAILED ITR LIST'!AC:AC,"CLOSED") -> 0 | F17: =D17-E17 -> 80 | O17: =SUM(H17:N17) -> 0 | R17: PS5 - Milestone B | S17: =COUNTIFS('DETAILED ITR LIST'!AD:AD,"PS5 - Milestone B",'DETAILED ITR LIST'!K:K,"P - Piping & Vessel",'DETAILED ITR LIST'!F:F,"TP") -> 225 | T17: =COUNTIFS('DETAILED ITR LIST'!AD:AD,"PS5 - Milestone B",'DETAILED ITR LIST'!K:K,"P - Piping & Vessel",'DETAILED ITR LIST'!F:F,"TP",'DETAILED ITR LIST'!AC:AC,"CLOSED") -> 158 | U17: =S17-T17 -> 67 | V17: =T17/S17 -> 0.70222222
B18: PS5 - Milestone E | C18: 10 | D18: =COUNTIFS('DETAILED ITR LIST'!AD:AD,"PS5 - Milestone E") -> 589 | E18: =COUNTIFS('DETAILED ITR LIST'!AD:AD,"PS5 - Milestone E",'DETAILED ITR LIST'!AC:AC,"Closed") -> 117 | F18: =D18-E18 -> 472 | O18: =E18/D18 -> 0.19864177 | R18: PS5 - Milestone D | S18: =COUNTIFS('DETAILED ITR LIST'!AD:AD,"PS5 - Milestone D",'DETAILED ITR LIST'!K:K,"P - Piping & Vessel",'DETAILED ITR LIST'!F:F,"TP") -> 360 | T18: =COUNTIFS('DETAILED ITR LIST'!AD:AD,"PS5 - Milestone D",'DETAILED ITR LIST'!K:K,"P - Piping & Vessel",'DETAILED ITR LIST'!F:F,"TP",'DETAILED ITR LIST'!AC:AC,"CLOSED") -> 239 | U18: =S18-T18 -> 121 | V18: =T18/S18 -> 0.66388889
B19: E - Electrical | D19: =COUNTIFS('DETAILED ITR LIST'!AD:AD,"PS5 - Milestone E",'DETAILED ITR LIST'!K:K,"E - Electrical") -> 194 | E19: =COUNTIFS('DETAILED ITR LIST'!AD:AD,"PS5 - Milestone E",'DETAILED ITR LIST'!K:K,"E - Electrical",'DETAILED ITR LIST'!AC:AC,"CLOSED") -> 18 | F19: =D19-E19 -> 176 | L19: 1 | O19: =SUM(H19:N19) -> 1 | R19: PS5 - Milestone E | S19: =COUNTIFS('DETAILED ITR LIST'!AD:AD,"PS5 - Milestone E",'DETAILED ITR LIST'!K:K,"P - Piping & Vessel",'DETAILED ITR LIST'!F:F,"TP") -> 90 | T19: =COUNTIFS('DETAILED ITR LIST'!AD:AD,"PS5 - Milestone E",'DETAILED ITR LIST'!K:K,"P - Piping & Vessel",'DETAILED ITR LIST'!F:F,"TP",'DETAILED ITR LIST'!AC:AC,"CLOSED") -> 52 | U19: =S19-T19 -> 38 | V19: =T19/S19 -> 0.57777778
B20: I - Instrumentation | D20: =COUNTIFS('DETAILED ITR LIST'!AD:AD,"PS5 - Milestone E",'DETAILED ITR LIST'!K:K,"I - Instrumentation") -> 223 | E20: =COUNTIFS('DETAILED ITR LIST'!AD:AD,"PS5 - Milestone E",'DETAILED ITR LIST'!K:K,"I - Instrumentation",'DETAILED ITR LIST'!AC:AC,"CLOSED") -> 3 | F20: =D20-E20 -> 220 | L20: 3 | O20: =SUM(H20:N20) -> 3 | R20: PS5 - Milestone H | S20: =COUNTIFS('DETAILED ITR LIST'!AD:AD,"PS5 - Milestone H",'DETAILED ITR LIST'!K:K,"P - Piping & Vessel",'DETAILED ITR LIST'!F:F,"TP") -> 25 | T20: =COUNTIFS('DETAILED ITR LIST'!AD:AD,"PS5 - Milestone H",'DETAILED ITR LIST'!K:K,"P - Piping & Vessel",'DETAILED ITR LIST'!F:F,"TP",'DETAILED ITR LIST'!AC:AC,"CLOSED") -> 18 | U20: =S20-T20 -> 7 | V20: =T20/S20 -> 0.72
B21: M - Mechanical | D21: =COUNTIFS('DETAILED ITR LIST'!AD:AD,"PS5 - Milestone E",'DETAILED ITR LIST'!K:K,"M - Mechanical") -> 29 | E21: =COUNTIFS('DETAILED ITR LIST'!AD:AD,"PS5 - Milestone E",'DETAILED ITR LIST'!K:K,"M - Mechanical",'DETAILED ITR LIST'!AC:AC,"CLOSED") -> 29 | F21: =D21-E21 -> 0 | O21: =SUM(H21:N21) -> 0 | R21: GRAND TOTAL | S21: =SUM(S17:S20) -> 700 | T21: =SUM(T17:T20) -> 467 | U21: =S21-T21 -> 233 | V21: =T21/S21 -> 0.66714286
B22: P - Piping & Vessel | D22: =COUNTIFS('DETAILED ITR LIST'!AD:AD,"PS5 - Milestone E",'DETAILED ITR LIST'!K:K,"P - Piping & Vessel") -> 129 | E22: =COUNTIFS('DETAILED ITR LIST'!AD:AD,"PS5 - Milestone E",'DETAILED ITR LIST'!K:K,"P - Piping & Vessel",'DETAILED ITR LIST'!AC:AC,"CLOSED") -> 67 | F22: =D22-E22 -> 62 | K22: 3 | L22: 3 | M22: 7 | N22: 5 | O22: =SUM(H22:N22) -> 18
B23: T - Telecom | D23: =COUNTIFS('DETAILED ITR LIST'!AD:AD,"PS5 - Milestone E",'DETAILED ITR LIST'!K:K,"T - Telecom") -> 14 | E23: =COUNTIFS('DETAILED ITR LIST'!AD:AD,"PS5 - Milestone E",'DETAILED ITR LIST'!K:K,"T - Telecom",'DETAILED ITR LIST'!AC:AC,"CLOSED") -> 0 | F23: =D23-E23 -> 14 | O23: =SUM(H23:N23) -> 0
B24: PS5 - Milestone H | C24: 3 | D24: =COUNTIFS('DETAILED ITR LIST'!AD:AD,"PS5 - Milestone H") -> 154 | E24: =COUNTIFS('DETAILED ITR LIST'!AD:AD,"PS5 - Milestone H",'DETAILED ITR LIST'!AC:AC,"Closed") -> 34 | F24: =D24-E24 -> 120 | O24: =E24/D24 -> 0.22077922
B25: E - Electrical | D25: =COUNTIFS('DETAILED ITR LIST'!AD:AD,"PS5 - Milestone H",'DETAILED ITR LIST'!K:K,"E - Electrical") -> 35 | E25: =COUNTIFS('DETAILED ITR LIST'!AD:AD,"PS5 - Milestone H",'DETAILED ITR LIST'!K:K,"E - Electrical",'DETAILED ITR LIST'!AC:AC,"CLOSED") -> 7 | F25: =D25-E25 -> 28 | N25: 3 | O25: =SUM(H25:N25) -> 3
B26: I - Instrumentation | D26: =COUNTIFS('DETAILED ITR LIST'!AD:AD,"PS5 - Milestone H",'DETAILED ITR LIST'!K:K,"I - Instrumentation") -> 76 | E26: =COUNTIFS('DETAILED ITR LIST'!AD:AD,"PS5 - Milestone H",'DETAILED ITR LIST'!K:K,"I - Instrumentation",'DETAILED ITR LIST'!AC:AC,"CLOSED") -> 0 | F26: =D26-E26 -> 76 | O26: =SUM(H26:N26) -> 0
B27: M - Mechanical | D27: =COUNTIFS('DETAILED ITR LIST'!AD:AD,"PS5 - Milestone H",'DETAILED ITR LIST'!K:K,"M - Mechanical") -> 6 | E27: =COUNTIFS('DETAILED ITR LIST'!AD:AD,"PS5 - Milestone H",'DETAILED ITR LIST'!K:K,"M - Mechanical",'DETAILED ITR LIST'!AC:AC,"CLOSED") -> 6 | F27: =D27-E27 -> 0 | K27: 2 | O27: =SUM(H27:N27) -> 2
B28: P - Piping & Vessel | D28: =COUNTIFS('DETAILED ITR LIST'!AD:AD,"PS5 - Milestone H",'DETAILED ITR LIST'!K:K,"P - Piping & Vessel") -> 35 | E28: =COUNTIFS('DETAILED ITR LIST'!AD:AD,"PS5 - Milestone H",'DETAILED ITR LIST'!K:K,"P - Piping & Vessel",'DETAILED ITR LIST'!AC:AC,"CLOSED") -> 21 | F28: =D28-E28 -> 14 | O28: =SUM(H28:N28) -> 0
B29: T - Telecom | D29: =COUNTIFS('DETAILED ITR LIST'!AD:AD,"PS5 - Milestone H",'DETAILED ITR LIST'!K:K,"T - Telecom") -> 2 | E29: =COUNTIFS('DETAILED ITR LIST'!AD:AD,"PS5 - Milestone H",'DETAILED ITR LIST'!K:K,"T - Telecom",'DETAILED ITR LIST'!AC:AC,"CLOSED") -> 0 | F29: =D29-E29 -> 2 | O29: =SUM(H29:N29) -> 0
B30: Grand Total | C30: 72 | D30: =SUM(D7:D11,D13:D17,D19:D23,D25:D29) -> 4144 | E30: =SUM(E7:E11,E13:E17,E19:E23,E25:E29) -> 1098 | F30: =SUM(F7:F11,F13:F17,F19:F23,F25:F29) -> 3046 | G30: =SUM(G7:G11,G13:G17,G19:G23,G25:G29) -> 0 | H30: =SUM(H7:H11,H13:H17,H19:H23,H25:H29) -> 16 | I30: =SUM(I7:I11,I13:I17,I19:I23,I25:I29) -> 0 | J30: =SUM(J7:J11,J13:J17,J19:J23,J25:J29) -> 0 | K30: =SUM(K7:K11,K13:K17,K19:K23,K25:K29) -> 23 | ... O30: =SUM(O7:O11,O13:O17,O19:O23,O25:O29) -> 131

Sheet 1ST PRIORITY MANTRAC
A1: TASK ID | B1: Asset - Tag | C1: Asset Pack ID | D1: Cable Pack ID | E1: Pipe Pack ID | F1: Loop Name | G1: Description | H1: Category (Summary) | I1: Discipline | J1: Task Type (Name) | K1: Discipline (Summary) | L1: Asset - Description | M1: Systemization - Process Plant ID | N1: Responsible Company (Summary) | O1: Actual Duration | P1: Scheduled Duration | Q1: Task Duration | R1: Title - Actual MH/Person | S1: Title - Planned MH/Person | T1: Field005 (Custom) | U1: Physical Location - Area (Summary) | V1: Systemization - Subsystem (Summary) | W1: Closing Date | X1: Subsystem ID | Y1: Priority | Z1: Priority | AA1: Test Form - Description | AB1: Asset Discipline | AC1: Task State | AD1: Priority | AE1: RFC | AF1: P-1,2,3
A2: T-00018-0192 | B2: PS5-61-IU-0001A | G2: CPX02 - Power transformer | H2: PCOM - Precommissioning | I2: E | J2: Conformity Check | K2: E - Electrical | L2: 11/33kV Transformer - 6.8 MVA | M2: EACOP | N2: CPP AGI | Q2: 16 | U2: PS5 - TZA - PS5 - Tanzania | V2: PS5-60-01 - Power Generation Package A | X2: PS5-60-01 | AA2: Power Transformer | AB2: E | AC2: To be completed | AD2: PS5 - Milestone B | AE2: =VLOOKUP(A:A,SUMMERY!AA:AC,2,FALSE) -> 46220 | AF2: =VLOOKUP(A:A,SUMMERY!AA:AC,3,FALSE) -> Priority-1
A3: T-00018-0193 | B3: PS5-61-IU-0001B | G3: CPX02 - Power transformer | H3: PCOM - Precommissioning | I3: E | J3: Conformity Check | K3: E - Electrical | L3: 11/33kV Transformer - 6.8 MVA | M3: EACOP | N3: CPP AGI | Q3: 16 | U3: PS5 - TZA - PS5 - Tanzania | V3: PS5-60-04 - Power Generation Package B | X3: PS5-60-04 | AA3: Power Transformer | AB3: E | AC3: To be completed | AD3: PS5 - Milestone B | AE3: =VLOOKUP(A:A,SUMMERY!AA:AC,2,FALSE) -> 46233 | AF3: =VLOOKUP(A:A,SUMMERY!AA:AC,3,FALSE) -> Priority-1
A4: T-00022-3334 | B4: PS5-60-IJ-0001A-CH04 | G4: CPX08 - HV Power Cable | H4: PCOM - Precommissioning | I4: E | J4: Conformity Check | K4: E - Electrical | L4: Cable FROM PS5-60-GE-8100A TO PS5-60-IJ-0001A | M4: EACOP | N4: CPP AGI | Q4: 4 | T4: TZ-MID-68-WPR2-150101 | U4: PS5 - TZA - PS5 - Tanzania | V4: PS5-60-01 - Power Generation Package A | W4: 46088.478 | X4: PS5-60-01 | AA4: HV Power Cable | AB4: E | AC4: Closed | AD4: PS5 - Milestone B | AE4: =VLOOKUP(A:A,SUMMERY!AA:AC,2,FALSE) -> 46220 | AF4: =VLOOKUP(A:A,SUMMERY!AA:AC,3,FALSE) -> Priority-1
A5: T-00022-3335 | B5: PS5-60-IJ-0001B-CH04 | G5: CPX08 - HV Power Cable | H5: PCOM - Precommissioning | I5: E | J5: Conformity Check | K5: E - Electrical | L5: Cable FROM PS5-60-GE-8100B TO PS5-60-IJ-0001B | M5: EACOP | N5: CPP AGI | Q5: 4 | T5: TZ-MID-68-WPR2-150101 | U5: PS5 - TZA - PS5 - Tanzania | V5: PS5-60-04 - Power Generation Package B | W5: 46088.483 | X5: PS5-60-04 | AA5: HV Power Cable | AB5: E | AC5: Closed | AD5: PS5 - Milestone B | AE5: =VLOOKUP(A:A,SUMMERY!AA:AC,2,FALSE) -> 46233 | AF5: =VLOOKUP(A:A,SUMMERY!AA:AC,3,FALSE) -> Priority-1
A6: T-00022-3377 | B6: PS5-61-IJ-0001-CH01 | G6: CPX08 - HV Power Cable | H6: PCOM - Precommissioning | I6: E | J6: Conformity Check | K6: E - Electrical | L6: Cable FROM PS5-61-IU-0001A TO PS5-61-IJ-0001 | M6: EACOP | N6: CPP AGI | Q6: 4 | T6: TZ-MID-68-WPR2-150101 | U6: PS5 - TZA - PS5 - Tanzania | V6: PS5-60-01 - Power Generation Package A | W6: 46136.342 | X6: PS5-60-01 | AA6: HV Power Cable | AB6: E | AC6: Closed | AD6: PS5 - Milestone B | AE6: =VLOOKUP(A:A,SUMMERY!AA:AC,2,FALSE) -> 46220 | AF6: =VLOOKUP(A:A,SUMMERY!AA:AC,3,FALSE) -> Priority-1
A7: T-00022-3378 | B7: PS5-61-IJ-0001-CH02 | G7: CPX08 - HV Power Cable | H7: PCOM - Precommissioning | I7: E | J7: Conformity Check | K7: E - Electrical | L7: Cable FROM PS5-61-IU-0001A TO PS5-61-IJ-0001 | M7: EACOP | N7: CPP AGI | Q7: 4 | T7: TZ-MID-68-WPR2-150101 | U7: PS5 - TZA - PS5 - Tanzania | V7: PS5-60-01 - Power Generation Package A | W7: 46136.541 | X7: PS5-60-01 | AA7: HV Power Cable | AB7: E | AC7: Closed | AD7: PS5 - Milestone B | AE7: =VLOOKUP(A:A,SUMMERY!AA:AC,2,FALSE) -> 46220 | AF7: =VLOOKUP(A:A,SUMMERY!AA:AC,3,FALSE) -> Priority-1
A8: T-00022-3379 | B8: PS5-61-IJ-0001-CH03 | G8: CPX08 - HV Power Cable | H8: PCOM - Precommissioning | I8: E | J8: Conformity Check | K8: E - Electrical | L8: Cable FROM PS5-61-IU-0001A TO PS5-61-IJ-0001 | M8: EACOP | N8: CPP AGI | Q8: 4 | T8: TZ-MID-68-WPR2-150101 | U8: PS5 - TZA - PS5 - Tanzania | V8: PS5-60-01 - Power Generation Package A | W8: 46136.542 | X8: PS5-60-01 | AA8: HV Power Cable | AB8: E | AC8: Closed | AD8: PS5 - Milestone B | AE8: =VLOOKUP(A:A,SUMMERY!AA:AC,2,FALSE) -> 46220 | AF8: =VLOOKUP(A:A,SUMMERY!AA:AC,3,FALSE) -> Priority-1
A9: T-00022-3380 | B9: PS5-61-IJ-0001-CH04 | G9: CPX08 - HV Power Cable | H9: PCOM - Precommissioning | I9: E | J9: Conformity Check | K9: E - Electrical | L9: Cable FROM PS5-61-IU-0001B TO PS5-61-IJ-0001 | M9: EACOP | N9: CPP AGI | Q9: 4 | T9: TZ-MID-68-WPR2-150101 | U9: PS5 - TZA - PS5 - Tanzania | V9: PS5-60-04 - Power Generation Package B | W9: 46136.542 | X9: PS5-60-04 | AA9: HV Power Cable | AB9: E | AC9: Closed | AD9: PS5 - Milestone B | AE9: =VLOOKUP(A:A,SUMMERY!AA:AC,2,FALSE) -> 46233 | AF9: =VLOOKUP(A:A,SUMMERY!AA:AC,3,FALSE) -> Priority-1
A10: T-00022-3381 | B10: PS5-61-IJ-0001-CH05 | G10: CPX08 - HV Power Cable | H10: PCOM - Precommissioning | I10: E | J10: Conformity Check | K10: E - Electrical | L10: Cable FROM PS5-61-IU-0001B TO PS5-61-IJ-0001 | M10: EACOP | N10: CPP AGI | Q10: 4 | T10: TZ-MID-68-WPR2-150101 | U10: PS5 - TZA - PS5 - Tanzania | V10: PS5-60-04 - Power Generation Package B | W10: 46136.542 | X10: PS5-60-04 | AA10: HV Power Cable | AB10: E | AC10: Closed | AD10: PS5 - Milestone B | AE10: =VLOOKUP(A:A,SUMMERY!AA:AC,2,FALSE) -> 46233 | AF10: =VLOOKUP(A:A,SUMMERY!AA:AC,3,FALSE) -> Priority-1
A11: T-00022-3382 | B11: PS5-61-IJ-0001-CH06 | G11: CPX08 - HV Power Cable | H11: PCOM - Precommissioning | I11: E | J11: Conformity Check | K11: E - Electrical | L11: Cable FROM PS5-61-IU-0001B TO PS5-61-IJ-0001 | M11: EACOP | N11: CPP AGI | Q11: 4 | T11: TZ-MID-68-WPR2-150101 | U11: PS5 - TZA - PS5 - Tanzania | V11: PS5-60-04 - Power Generation Package B | W11: 46136.575 | X11: PS5-60-04 | AA11: HV Power Cable | AB11: E | AC11: Closed | AD11: PS5 - Milestone B | AE11: =VLOOKUP(A:A,SUMMERY!AA:AC,2,FALSE) -> 46233 | AF11: =VLOOKUP(A:A,SUMMERY!AA:AC,3,FALSE) -> Priority-1
A12: T-00022-3410 | B12: PS5-61-IU-0001A-CH01 | G12: CPX08 - HV Power Cable | H12: PCOM - Precommissioning | I12: E | J12: Conformity Check | K12: E - Electrical | L12: Cable FROM PS5-60-GE-8100A TO PS5-61-IU-0001A | M12: EACOP | N12: CPP AGI | Q12: 4 | T12: TZ-MID-68-WPR2-150101 | U12: PS5 - TZA - PS5 - Tanzania | V12: PS5-60-01 - Power Generation Package A | W12: 46071.541 | X12: PS5-60-01 | AA12: HV Power Cable | AB12: E | AC12: Closed | AD12: PS5 - Milestone B | AE12: =VLOOKUP(A:A,SUMMERY!AA:AC,2,FALSE) -> 46220 | AF12: =VLOOKUP(A:A,SUMMERY!AA:AC,3,FALSE) -> Priority-1
A13: T-00022-3411 | B13: PS5-61-IU-0001A-CH02 | G13: CPX08 - HV Power Cable | H13: PCOM - Precommissioning | I13: E | J13: Conformity Check | K13: E - Electrical | L13: Cable FROM PS5-60-GE-8100A TO PS5-61-IU-0001A | M13: EACOP | N13: CPP AGI | Q13: 4 | T13: TZ-MID-68-WPR2-150101 | U13: PS5 - TZA - PS5 - Tanzania | V13: PS5-60-01 - Power Generation Package A | W13: 46071.544 | X13: PS5-60-01 | AA13: HV Power Cable | AB13: E | AC13: Closed | AD13: PS5 - Milestone B | AE13: =VLOOKUP(A:A,SUMMERY!AA:AC,2,FALSE) -> 46220 | AF13: =VLOOKUP(A:A,SUMMERY!AA:AC,3,FALSE) -> Priority-1
A14: T-00022-3412 | B14: PS5-61-IU-0001A-CH03 | G14: CPX08 - HV Power Cable | H14: PCOM - Precommissioning | I14: E | J14: Conformity Check | K14: E - Electrical | L14: Cable FROM PS5-60-GE-8100A TO PS5-61-IU-0001A | M14: EACOP | N14: CPP AGI | Q14: 4 | T14: TZ-MID-68-WPR2-150101 | U14: PS5 - TZA - PS5 - Tanzania | V14: PS5-60-01 - Power Generation Package A | W14: 46071.546 | X14: PS5-60-01 | AA14: HV Power Cable | AB14: E | AC14: Closed | AD14: PS5 - Milestone B | AE14: =VLOOKUP(A:A,SUMMERY!AA:AC,2,FALSE) -> 46220 | AF14: =VLOOKUP(A:A,SUMMERY!AA:AC,3,FALSE) -> Priority-1
A15: T-00022-3413 | B15: PS5-61-IU-0001B-CH01 | G15: CPX08 - HV Power Cable | H15: PCOM - Precommissioning | I15: E | J15: Conformity Check | K15: E - Electrical | L15: Cable FROM PS5-60-GE-8100B TO PS5-61-IU-0001B | M15: EACOP | N15: CPP AGI | Q15: 4 | T15: TZ-MID-68-WPR2-150101 | U15: PS5 - TZA - PS5 - Tanzania | V15: PS5-60-04 - Power Generation Package B | W15: 46071.548 | X15: PS5-60-04 | AA15: HV Power Cable | AB15: E | AC15: Closed | AD15: PS5 - Milestone B | AE15: =VLOOKUP(A:A,SUMMERY!AA:AC,2,FALSE) -> 46233 | AF15: =VLOOKUP(A:A,SUMMERY!AA:AC,3,FALSE) -> Priority-1
... A17: T-00022-3415 | B17: PS5-61-IU-0001B-CH03 | G17: CPX08 - HV Power Cable | H17: PCOM - Precommissioning | I17: E | J17: Conformity Check | K17: E - Electrical | L17: Cable FROM PS5-60-GE-8100B TO PS5-61-IU-0001B | M17: EACOP | N17: CPP AGI | Q17: 4 | T17: TZ-MID-68-WPR2-150101 | U17: PS5 - TZA - PS5 - Tanzania | V17: PS5-60-04 - Power Generation Package B | W17: 46071.551 | X17: PS5-60-04 | AA17: HV Power Cable | AB17: E | AC17: Closed | AD17: PS5 - Milestone B | AE17: =VLOOKUP(A:A,SUMMERY!AA:AC,2,FALSE) -> 46233 | AF17: =VLOOKUP(A:A,SUMMERY!AA:AC,3,FALSE) -> Priority-1
A18: T-00023-10536 | B18: PS5-60-IN-0002A-CG01 | G18: CPX09 - LV Power Cable | H18: PCOM - Precommissioning | I18: E | J18: Conformity Check | K18: E - Electrical | L18: Cable FROM PS5-60-IH-0001A TO PS5-60-IN-0002A | M18: EACOP | N18: CPP AGI | Q18: 1 | S18: 1 | U18: PS5 - TZA - PS5 - Tanzania | V18: PS5-60-57 - Fuel Conditioning Module PS5-60-UZ-8900A (UCP) | X18: PS5-60-57 | AA18: LV Power Cable | AB18: E | AC18: To be completed | AD18: PS5 - Milestone B | AE18: =VLOOKUP(A:A,SUMMERY!AA:AC,2,FALSE) -> 46220 | AF18: =VLOOKUP(A:A,SUMMERY!AA:AC,3,FALSE) -> Priority-1
A19: T-00023-10537 | B19: PS5-60-IN-0002B-CG01 | G19: CPX09 - LV Power Cable | H19: PCOM - Precommissioning | I19: E | J19: Conformity Check | K19: E - Electrical | L19: Cable FROM PS5-60-IH-0001B TO PS5-60-IN-0002B | M19: EACOP | N19: CPP AGI | Q19: 1 | S19: 1 | U19: PS5 - TZA - PS5 - Tanzania | V19: PS5-60-59 - Fuel Conditioning Module PS5-60-UZ-8900B (UCP) | X19: PS5-60-59 | AA19: LV Power Cable | AB19: E | AC19: To be completed | AD19: PS5 - Milestone B | AE19: =VLOOKUP(A:A,SUMMERY!AA:AC,2,FALSE) -> 46234 | AF19: =VLOOKUP(A:A,SUMMERY!AA:AC,3,FALSE) -> Priority-1
A20: T-00023-10593 | B20: PS5-60-IH-0001A-CG01 | G20: CPX09 - LV Power Cable | H20: PCOM - Precommissioning | I20: E | J20: Conformity Check | K20: E - Electrical | L20: Cable FROM PS5-61-IK-0003 TO PS5-60-IH-0001A | M20: EACOP | N20: CPP AGI | Q20: 1 | S20: 1 | U20: PS5 - TZA - PS5 - Tanzania | V20: PS5-60-03 - Power Gen Package A Generator Auxiliary MCCs & DBs | X20: PS5-60-03 | AA20: LV Power Cable | AB20: E | AC20: To be completed | AD20: PS5 - Milestone B | AE20: =VLOOKUP(A:A,SUMMERY!AA:AC,2,FALSE) -> 46220 | AF20: =VLOOKUP(A:A,SUMMERY!AA:AC,3,FALSE) -> Priority-1
A21: T-00023-10594 | B21: PS5-60-IH-0001B-CG01 | G21: CPX09 - LV Power Cable | H21: PCOM - Precommissioning | I21: E | J21: Conformity Check | K21: E - Electrical | L21: Cable FROM PS5-61-IK-0003 TO PS5-60-IH-0001B | M21: EACOP | N21: CPP AGI | Q21: 1 | S21: 1 | U21: PS5 - TZA - PS5 - Tanzania | V21: PS5-60-06 - Power Gen Package B Generator Auxiliary MCCs & DBs | X21: PS5-60-06 | AA21: LV Power Cable | AB21: E | AC21: To be completed | AD21: PS5 - Milestone B | AE21: =VLOOKUP(A:A,SUMMERY!AA:AC,2,FALSE) -> 46233 | AF21: =VLOOKUP(A:A,SUMMERY!AA:AC,3,FALSE) -> Priority-1
A22: T-00023-10600 | B22: PS5-60-IH-0002-CG01 | G22: CPX09 - LV Power Cable | H22: PCOM - Precommissioning | I22: E | J22: Conformity Check | K22: E - Electrical | L22: Cable FROM PS5-61-IK-0003 TO PS5-60-IH-0002 | M22: EACOP | N22: CPP AGI | Q22: 1 | S22: 1 | U22: PS5 - TZA - PS5 - Tanzania | V22: PS5-60-22 - Power Gen Master UCP | X22: PS5-60-22 | AA22: LV Power Cable | AB22: E | AC22: To be completed | AD22: PS5 - Milestone B | AE22: =VLOOKUP(A:A,SUMMERY!AA:AC,2,FALSE) -> 46233 | AF22: =VLOOKUP(A:A,SUMMERY!AA:AC,3,FALSE) -> Priority-1
A23: T-00023-10601 | B23: PS5-60-IH-0002-CG02 | G23: CPX09 - LV Power Cable | H23: PCOM - Precommissioning | I23: E | J23: Conformity Check | K23: E - Electrical | L23: Cable FROM PS5-61-IK-0003 TO PS5-60-IH-0002 | M23: EACOP | N23: CPP AGI | Q23: 1 | S23: 1 | U23: PS5 - TZA - PS5 - Tanzania | V23: PS5-60-22 - Power Gen Master UCP | X23: PS5-60-22 | AA23: LV Power Cable | AB23: E | AC23: To be completed | AD23: PS5 - Milestone B | AE23: =VLOOKUP(A:A,SUMMERY!AA:AC,2,FALSE) -> 46233 | AF23: =VLOOKUP(A:A,SUMMERY!AA:AC,3,FALSE) -> Priority-1
A24: T-00023-10887 | B24: PS5-60-BE-0007A-CL02 | G24: CPX09 - LV Power Cable | H24: PCOM - Precommissioning | I24: E | J24: Conformity Check | K24: E - Electrical | L24: Cable FROM PS5-60-IN-0002A TO PS5-60-BE-0007A | M24: EACOP | N24: CPP AGI | Q24: 1 | S24: 1 | U24: PS5 - TZA - PS5 - Tanzania | V24: PS5-60-56 - Fuel Conditioning Module PS5-60-UZ-8900A | X24: PS5-60-56 | AA24: LV Power Cable | AB24: E | AC24: To be completed | AD24: PS5 - Milestone B | AE24: =VLOOKUP(A:A,SUMMERY!AA:AC,2,FALSE) -> 46233 | AF24: =VLOOKUP(A:A,SUMMERY!AA:AC,3,FALSE) -> Priority-1
A25: T-00023-10888 | B25: PS5-60-BE-0007A-CL03 | G25: CPX09 - LV Power Cable | H25: PCOM - Precommissioning | I25: E | J25: Conformity Check | K25: E - Electrical | L25: Cable FROM PS5-60-IN-0002A TO PS5-60-BE-0007A | M25: EACOP | N25: CPP AGI | Q25: 1 | S25: 1 | U25: PS5 - TZA - PS5 - Tanzania | V25: PS5-60-56 - Fuel Conditioning Module PS5-60-UZ-8900A | X25: PS5-60-56 | AA25: LV Power Cable | AB25: E | AC25: To be completed | AD25: PS5 - Milestone B | AE25: =VLOOKUP(A:A,SUMMERY!AA:AC,2,FALSE) -> 46233 | AF25: =VLOOKUP(A:A,SUMMERY!AA:AC,3,FALSE) -> Priority-1
A26: T-00023-10889 | B26: PS5-60-BE-0007B-CL02 | G26: CPX09 - LV Power Cable | H26: PCOM - Precommissioning | I26: E | J26: Conformity Check | K26: E - Electrical | L26: Cable FROM PS5-60-IN-0002B TO PS5-60-BE-0007B | M26: EACOP | N26: CPP AGI | Q26: 1 | S26: 1 | U26: PS5 - TZA - PS5 - Tanzania | V26: PS5-60-58 - Fuel Conditioning Module PS5-60-UZ-8900B | X26: PS5-60-58 | AA26: LV Power Cable | AB26: E | AC26: To be completed | AD26: PS5 - Milestone B | AE26: =VLOOKUP(A:A,SUMMERY!AA:AC,2,FALSE) -> 46234 | AF26: =VLOOKUP(A:A,SUMMERY!AA:AC,3,FALSE) -> Priority-1
A27: T-00023-10890 | B27: PS5-60-BE-0007B-CL03 | G27: CPX09 - LV Power Cable | H27: PCOM - Precommissioning | I27: E | J27: Conformity Check | K27: E - Electrical | L27: Cable FROM PS5-60-IN-0002B TO PS5-60-BE-0007B | M27: EACOP | N27: CPP AGI | Q27: 1 | S27: 1 | U27: PS5 - TZA - PS5 - Tanzania | V27: PS5-60-58 - Fuel Conditioning Module PS5-60-UZ-8900B | X27: PS5-60-58 | AA27: LV Power Cable | AB27: E | AC27: To be completed | AD27: PS5 - Milestone B | AE27: =VLOOKUP(A:A,SUMMERY!AA:AC,2,FALSE) -> 46234 | AF27: =VLOOKUP(A:A,SUMMERY!AA:AC,3,FALSE) -> Priority-1
A28: T-00023-10901 | B28: PS5-60-ISO-62800A-CL01 | G28: CPX09 - LV Power Cable | H28: PCOM - Precommissioning | I28: E | J28: Conformity Check | K28: E - Electrical | L28: Cable FROM PS5-60-IH-0001A TO PS5-60-ISO-62800A | M28: EACOP | N28: CPP AGI | Q28: 1 | S28: 1 | U28: PS5 - TZA - PS5 - Tanzania | V28: PS5-60-03 - Power Gen Package A Generator Auxiliary MCCs & DBs | X28: PS5-60-03 | AA28: LV Power Cable | AB28: E | AC28: To be completed | AD28: PS5 - Milestone B | AE28: =VLOOKUP(A:A,SUMMERY!AA:AC,2,FALSE) -> 46220 | AF28: =VLOOKUP(A:A,SUMMERY!AA:AC,3,FALSE) -> Priority-1
A29: T-00023-4978 | B29: PS5-60-BE-0001-CL01 | G29: CPX09 - LV Power Cable | H29: PCOM - Precommissioning | I29: E | J29: Conformity Check | K29: E - Electrical | L29: Cable FROM PS5-60-IH-0002 TO PS5-60-BE-0001 | M29: EACOP | N29: CPP AGI | Q29: 1 | T29: TZ-MID-68-WPR2-150101 | U29: PS5 - TZA - PS5 - Tanzania | V29: PS5-60-27 - Compressed Air Starting Skid | X29: PS5-60-27 | AA29: LV Power Cable | AB29: E | AC29: To be completed | AD29: PS5 - Milestone B | AE29: =VLOOKUP(A:A,SUMMERY!AA:AC,2,FALSE) -> 46220 | AF29: =VLOOKUP(A:A,SUMMERY!AA:AC,3,FALSE) -> Priority-1
A30: T-00023-4979 | B30: PS5-60-BE-0001-CL02 | G30: CPX09 - LV Power Cable | H30: PCOM - Precommissioning | I30: E | J30: Conformity Check | K30: E - Electrical | L30: Cable FROM PS5-60-IH-0002 TO PS5-60-BE-0001 | M30: EACOP | N30: CPP AGI | Q30: 1 | T30: TZ-MID-68-WPR2-150101 | U30: PS5 - TZA - PS5 - Tanzania | V30: PS5-60-27 - Compressed Air Starting Skid | X30: PS5-60-27 | AA30: LV Power Cable | AB30: E | AC30: To be completed | AD30: PS5 - Milestone B | AE30: =VLOOKUP(A:A,SUMMERY!AA:AC,2,FALSE) -> 46220 | AF30: =VLOOKUP(A:A,SUMMERY!AA:AC,3,FALSE) -> Priority-1
A31: T-00023-4981 | B31: PS5-60-BE-0001-CL04 | G31: CPX09 - LV Power Cable | H31: PCOM - Precommissioning | I31: E | J31: Conformity Check | K31: E - Electrical | L31: Cable FROM PS5-06-IG-0004B TO PS5-60-BE-0001 | M31: EACOP | N31: CPP AGI | Q31: 1 | T31: TZ-MID-68-WPR2-150101 | U31: PS5 - TZA - PS5 - Tanzania | V31: PS5-60-27 - Compressed Air Starting Skid | X31: PS5-60-27 | AA31: LV Power Cable | AB31: E | AC31: To be completed | AD31: PS5 - Milestone B | AE31: =VLOOKUP(A:A,SUMMERY!AA:AC,2,FALSE) -> 46220 | AF31: =VLOOKUP(A:A,SUMMERY!AA:AC,3,FALSE) -> Priority-1
A32: T-00023-4982 | B32: PS5-60-BE-0002-CL01 | G32: CPX09 - LV Power Cable | H32: PCOM - Precommissioning | I32: E | J32: Conformity Check | K32: E - Electrical | L32: Cable FROM PS5-60-IH-0002 TO PS5-60-BE-0002 | M32: EACOP | N32: CPP AGI | Q32: 1 | T32: TZ-MID-68-WPR2-150101 | U32: PS5 - TZA - PS5 - Tanzania | V32: PS5-60-26 - Instrument Air Compressor Skid | X32: PS5-60-26 | AA32: LV Power Cable | AB32: E | AC32: To be completed | AD32: PS5 - Milestone B | AE32: =VLOOKUP(A:A,SUMMERY!AA:AC,2,FALSE) -> 46220 | AF32: =VLOOKUP(A:A,SUMMERY!AA:AC,3,FALSE) -> Priority-1
A33: T-00023-4983 | B33: PS5-60-BE-0002-CL02 | G33: CPX09 - LV Power Cable | H33: PCOM - Precommissioning | I33: E | J33: Conformity Check | K33: E - Electrical | L33: Cable FROM PS5-60-IH-0002 TO PS5-60-BE-0002 | M33: EACOP | N33: CPP AGI | Q33: 1 | T33: TZ-MID-68-WPR2-150101 | U33: PS5 - TZA - PS5 - Tanzania | V33: PS5-60-26 - Instrument Air Compressor Skid | X33: PS5-60-26 | AA33: LV Power Cable | AB33: E | AC33: To be completed | AD33: PS5 - Milestone B | AE33: =VLOOKUP(A:A,SUMMERY!AA:AC,2,FALSE) -> 46220 | AF33: =VLOOKUP(A:A,SUMMERY!AA:AC,3,FALSE) -> Priority-1
