Workbook

Sheet Priority-1
B1: CPP AGI - E/I/T Static & Conformity Closure Summary by Subsystem
B2: Source: uploaded ovTasks_TestsPlanned_1369 (21).xlsx | Updated all 44 workbook subsystems | Company filter: CPP AGI | Disciplines combined: Electrical + Instrumentation + Telecom | Closed = Task State = Closed | Overall = Static Test + Conformity Check.
B4: Subsystem IDs | C4: Static Total | D4: Static Closed | E4: Static Balance | F4: Static Closed % | G4: Conformity Total | H4: Conformity Closed | I4: Conformity Balance | J4: Conformity Closed % | K4: Overall Total | L4: Overall Closed | M4: Overall Closed %
B5: =COUNTA(B17:B42) -> 26 | C5: =SUM(E17:E42) -> 453 | D5: =SUM(F17:F42) -> 383 | E5: =C5-D5 -> 70 | F5: =IF(C5=0,0,D5/C5) -> 0.84547461 | G5: =SUM(I17:I42) -> 715 | H5: =SUM(J17:J42) -> 595 | I5: =G5-H5 -> 120 | J5: =IF(G5=0,0,H5/G5) -> 0.83216783 | K5: =C5+G5 -> 1168 | L5: =D5+H5 -> 978 | M5: =IF(K5=0,0,L5/K5) -> 0.83732877
B8: Combined Summary
B9: Group | C9: Static Total | D9: Static Closed | E9: Static Balance | F9: Static Closed % | G9: Conformity Total | H9: Conformity Closed | I9: Conformity Balance | J9: Conformity Closed % | K9: Overall Total | L9: Overall Closed | M9: Overall Balance | N9: Overall Closed %
B10: All E/I/T Disciplines | C10: =SUM(E17:E42) -> 453 | D10: =SUM(F17:F42) -> 383 | E10: =C10-D10 -> 70 | F10: =IF(C10=0,0,D10/C10) -> 0.84547461 | G10: =SUM(I17:I42) -> 715 | H10: =SUM(J17:J42) -> 595 | I10: =G10-H10 -> 120 | J10: =IF(G10=0,0,H10/G10) -> 0.83216783 | K10: =C10+G10 -> 1168 | L10: =D10+H10 -> 978 | M10: =K10-L10 -> 190 | N10: =IF(K10=0,0,L10/K10) -> 0.83732877
A15: Priority-01 | R15: We cannot Close the below ITR's Right now
A16: Sl NO | B16: Subsystem ID | C16: Subsystem Description | D16: Disciplines Included | E16: Static Total | F16: Static Closed | G16: Static Balance | H16: Static Closed % | I16: Conformity Total | J16: Conformity Closed | K16: Conformity Balance | L16: Conformity Closed % | M16: Overall Total | N16: Overall Closed | O16: Overall Balance | P16: Overall Closed % | R16: Earthing | S16: Cable LUG (Hole dia Issue) | T16: Earthing Lightining Protection | U16: CAT6/MODbus/Fiber | V16: Transformer wall (Cables) | W16: Drum Not available(EACOP) | X16: Duplex filter JB & PIT Not find | Y16: Transformer | Z16: Total | AA16: Remarks as of 24-july-2026
A17: 1 | B17: PS4-91-01 | C17: Multicore cables & JB | D17: I | E17: =COUNTIFS('Exported from SC '!$X:$X,$B17,'Exported from SC '!$J:$J,"Static Test") -> 0 | F17: =COUNTIFS('Exported from SC '!$X:$X,$B17,'Exported from SC '!$J:$J,"Static Test",'Exported from SC '!$AC:$AC,"Closed") -> 0 | G17: =E17-F17 -> 0 | H17: =IF(E17=0,0,F17/E17) -> 0 | I17: =COUNTIFS('Exported from SC '!$X:$X,$B17,'Exported from SC '!$J:$J,"Conformity Check") -> 128 | J17: =COUNTIFS('Exported from SC '!$X:$X,$B17,'Exported from SC '!$J:$J,"Conformity Check",'Exported from SC '!$AC:$AC,"Closed") -> 128 | K17: =I17-J17 -> 0 | L17: =IF(I17=0,0,J17/I17) -> 1 | M17: =E17+I17 -> 128 | N17: =F17+J17 -> 128 | O17: =G17+K17 -> 0 | P17: =IF(M17=0,0,N17/M17) -> 1 | Z17: =SUM(R17:Y17) -> 0 | AC17: =COUNTIFS('[1]Exported from SC (10)'!$X:$X,$B17,'[1]Exported from SC (10)'!$J:$J,"Static Test") -> #VALUE! | AD17: =E17-AC17 -> #VALUE!
A18: 2 | B18: PS4-63-03 | C18: Electrical Earthing - Generator Building | D18: E | E18: =COUNTIFS('Exported from SC '!$X:$X,$B18,'Exported from SC '!$J:$J,"Static Test") -> 2 | F18: =COUNTIFS('Exported from SC '!$X:$X,$B18,'Exported from SC '!$J:$J,"Static Test",'Exported from SC '!$AC:$AC,"Closed") -> 0 | G18: =E18-F18 -> 2 | H18: =IF(E18=0,0,F18/E18) -> 0 | I18: =COUNTIFS('Exported from SC '!$X:$X,$B18,'Exported from SC '!$J:$J,"Conformity Check") -> 2 | J18: =COUNTIFS('Exported from SC '!$X:$X,$B18,'Exported from SC '!$J:$J,"Conformity Check",'Exported from SC '!$AC:$AC,"Closed") -> 0 | K18: =I18-J18 -> 2 | L18: =IF(I18=0,0,J18/I18) -> 0 | M18: =E18+I18 -> 4 | N18: =F18+J18 -> 0 | O18: =G18+K18 -> 4 | P18: =IF(M18=0,0,N18/M18) -> 0 | T18: 2 | Z18: =SUM(R18:Y18) -> 2 | AA18: 2 ITR with Punch A | AC18: =COUNTIFS('[1]Exported from SC (10)'!$X:$X,$B18,'[1]Exported from SC (10)'!$J:$J,"Static Test") -> #VALUE! | AD18: =E18-AC18 -> #VALUE!
A19: 3 | B19: PS4-63-01 | C19: Electrical Earthing | D19: E | E19: =COUNTIFS('Exported from SC '!$X:$X,$B19,'Exported from SC '!$J:$J,"Static Test") -> 34 | F19: =COUNTIFS('Exported from SC '!$X:$X,$B19,'Exported from SC '!$J:$J,"Static Test",'Exported from SC '!$AC:$AC,"Closed") -> 1 | G19: =E19-F19 -> 33 | H19: =IF(E19=0,0,F19/E19) -> 0.029411765 | I19: =COUNTIFS('Exported from SC '!$X:$X,$B19,'Exported from SC '!$J:$J,"Conformity Check") -> 34 | J19: =COUNTIFS('Exported from SC '!$X:$X,$B19,'Exported from SC '!$J:$J,"Conformity Check",'Exported from SC '!$AC:$AC,"Closed") -> 2 | K19: =I19-J19 -> 32 | L19: =IF(I19=0,0,J19/I19) -> 0.058823529 | M19: =E19+I19 -> 68 | N19: =F19+J19 -> 3 | O19: =G19+K19 -> 65 | P19: =IF(M19=0,0,N19/M19) -> 0.044117647 | R19: 65 | Z19: =SUM(R19:Y19) -> 65 | AA19: covered in above | AC19: =COUNTIFS('[1]Exported from SC (10)'!$X:$X,$B19,'[1]Exported from SC (10)'!$J:$J,"Static Test") -> #VALUE! | AD19: =E19-AC19 -> #VALUE!
A20: 4 | B20: PS4-60-27 | C20: Compressed Air Starting Skid | D20: E/I | E20: =COUNTIFS('Exported from SC '!$X:$X,$B20,'Exported from SC '!$J:$J,"Static Test") -> 4 | F20: =COUNTIFS('Exported from SC '!$X:$X,$B20,'Exported from SC '!$J:$J,"Static Test",'Exported from SC '!$AC:$AC,"Closed") -> 4 | G20: =E20-F20 -> 0 | H20: =IF(E20=0,0,F20/E20) -> 1 | I20: =COUNTIFS('Exported from SC '!$X:$X,$B20,'Exported from SC '!$J:$J,"Conformity Check") -> 6 | J20: =COUNTIFS('Exported from SC '!$X:$X,$B20,'Exported from SC '!$J:$J,"Conformity Check",'Exported from SC '!$AC:$AC,"Closed") -> 6 | K20: =I20-J20 -> 0 | L20: =IF(I20=0,0,J20/I20) -> 1 | M20: =E20+I20 -> 10 | N20: =F20+J20 -> 10 | O20: =G20+K20 -> 0 | P20: =IF(M20=0,0,N20/M20) -> 1 | Z20: =SUM(R20:Y20) -> 0 | AC20: =COUNTIFS('[1]Exported from SC (10)'!$X:$X,$B20,'[1]Exported from SC (10)'!$J:$J,"Static Test") -> #VALUE! | AD20: =E20-AC20 -> #VALUE!
A21: 5 | B21: PS4-60-42 | C21: Oil Mist Separator Skid PS4-60-VS-9100A | D21: E/I | E21: =COUNTIFS('Exported from SC '!$X:$X,$B21,'Exported from SC '!$J:$J,"Static Test") -> 2 | F21: =COUNTIFS('Exported from SC '!$X:$X,$B21,'Exported from SC '!$J:$J,"Static Test",'Exported from SC '!$AC:$AC,"Closed") -> 2 | G21: =E21-F21 -> 0 | H21: =IF(E21=0,0,F21/E21) -> 1 | I21: =COUNTIFS('Exported from SC '!$X:$X,$B21,'Exported from SC '!$J:$J,"Conformity Check") -> 4 | J21: =COUNTIFS('Exported from SC '!$X:$X,$B21,'Exported from SC '!$J:$J,"Conformity Check",'Exported from SC '!$AC:$AC,"Closed") -> 4 | K21: =I21-J21 -> 0 | L21: =IF(I21=0,0,J21/I21) -> 1 | M21: =E21+I21 -> 6 | N21: =F21+J21 -> 6 | O21: =G21+K21 -> 0 | P21: =IF(M21=0,0,N21/M21) -> 1 | Z21: =SUM(R21:Y21) -> 0 | AC21: =COUNTIFS('[1]Exported from SC (10)'!$X:$X,$B21,'[1]Exported from SC (10)'!$J:$J,"Static Test") -> #VALUE! | AD21: =E21-AC21 -> #VALUE!
A22: 6 | B22: PS4-60-43 | C22: Oil Mist Separator Skid PS4-60-VS-9100B | D22: E/I | E22: =COUNTIFS('Exported from SC '!$X:$X,$B22,'Exported from SC '!$J:$J,"Static Test") -> 2 | F22: =COUNTIFS('Exported from SC '!$X:$X,$B22,'Exported from SC '!$J:$J,"Static Test",'Exported from SC '!$AC:$AC,"Closed") -> 2 | G22: =E22-F22 -> 0 | H22: =IF(E22=0,0,F22/E22) -> 1 | I22: =COUNTIFS('Exported from SC '!$X:$X,$B22,'Exported from SC '!$J:$J,"Conformity Check") -> 4 | J22: =COUNTIFS('Exported from SC '!$X:$X,$B22,'Exported from SC '!$J:$J,"Conformity Check",'Exported from SC '!$AC:$AC,"Closed") -> 4 | K22: =I22-J22 -> 0 | L22: =IF(I22=0,0,J22/I22) -> 1 | M22: =E22+I22 -> 6 | N22: =F22+J22 -> 6 | O22: =G22+K22 -> 0 | P22: =IF(M22=0,0,N22/M22) -> 1 | Z22: =SUM(R22:Y22) -> 0 | AC22: =COUNTIFS('[1]Exported from SC (10)'!$X:$X,$B22,'[1]Exported from SC (10)'!$J:$J,"Static Test") -> #VALUE! | AD22: =E22-AC22 -> #VALUE!
A23: 7 | B23: PS4-60-26 | C23: Instrument Air Compressor Skid | D23: E/I | E23: =COUNTIFS('Exported from SC '!$X:$X,$B23,'Exported from SC '!$J:$J,"Static Test") -> 5 | F23: =COUNTIFS('Exported from SC '!$X:$X,$B23,'Exported from SC '!$J:$J,"Static Test",'Exported from SC '!$AC:$AC,"Closed") -> 5 | G23: =E23-F23 -> 0 | H23: =IF(E23=0,0,F23/E23) -> 1 | I23: =COUNTIFS('Exported from SC '!$X:$X,$B23,'Exported from SC '!$J:$J,"Conformity Check") -> 7 | J23: =COUNTIFS('Exported from SC '!$X:$X,$B23,'Exported from SC '!$J:$J,"Conformity Check",'Exported from SC '!$AC:$AC,"Closed") -> 7 | K23: =I23-J23 -> 0 | L23: =IF(I23=0,0,J23/I23) -> 1 | M23: =E23+I23 -> 12 | N23: =F23+J23 -> 12 | O23: =G23+K23 -> 0 | P23: =IF(M23=0,0,N23/M23) -> 1 | Z23: =SUM(R23:Y23) -> 0 | AC23: =COUNTIFS('[1]Exported from SC (10)'!$X:$X,$B23,'[1]Exported from SC (10)'!$J:$J,"Static Test") -> #VALUE! | AD23: =E23-AC23 -> #VALUE!
A24: 8 | B24: PS4-60-49 | C24: Lube Oil Separator Module PS4-60-UO-81100A | D24: E/I/T | E24: =COUNTIFS('Exported from SC '!$X:$X,$B24,'Exported from SC '!$J:$J,"Static Test") -> 8 | F24: =COUNTIFS('Exported from SC '!$X:$X,$B24,'Exported from SC '!$J:$J,"Static Test",'Exported from SC '!$AC:$AC,"Closed") -> 7 | G24: =E24-F24 -> 1 | H24: =IF(E24=0,0,F24/E24) -> 0.875 | I24: =COUNTIFS('Exported from SC '!$X:$X,$B24,'Exported from SC '!$J:$J,"Conformity Check") -> 10 | J24: =COUNTIFS('Exported from SC '!$X:$X,$B24,'Exported from SC '!$J:$J,"Conformity Check",'Exported from SC '!$AC:$AC,"Closed") -> 9 | K24: =I24-J24 -> 1 | L24: =IF(I24=0,0,J24/I24) -> 0.9 | M24: =E24+I24 -> 18 | N24: =F24+J24 -> 16 | O24: =G24+K24 -> 2 | P24: =IF(M24=0,0,N24/M24) -> 0.88888889 | U24: 2 | Z24: =SUM(R24:Y24) -> 2 | AA24: Scope to be clarify with EACOP and CPP headoffice | AC24: =COUNTIFS('[1]Exported from SC (10)'!$X:$X,$B24,'[1]Exported from SC (10)'!$J:$J,"Static Test") -> #VALUE! | AD24: =E24-AC24 -> #VALUE!
A25: 9 | B25: PS4-60-50 | C25: Lube Oil Separator Module PS4-60-UO-81100B | D25: E/I/T | E25: =COUNTIFS('Exported from SC '!$X:$X,$B25,'Exported from SC '!$J:$J,"Static Test") -> 8 | F25: =COUNTIFS('Exported from SC '!$X:$X,$B25,'Exported from SC '!$J:$J,"Static Test",'Exported from SC '!$AC:$AC,"Closed") -> 7 | G25: =E25-F25 -> 1 | H25: =IF(E25=0,0,F25/E25) -> 0.875 | I25: =COUNTIFS('Exported from SC '!$X:$X,$B25,'Exported from SC '!$J:$J,"Conformity Check") -> 10 | J25: =COUNTIFS('Exported from SC '!$X:$X,$B25,'Exported from SC '!$J:$J,"Conformity Check",'Exported from SC '!$AC:$AC,"Closed") -> 9 | K25: =I25-J25 -> 1 | L25: =IF(I25=0,0,J25/I25) -> 0.9 | M25: =E25+I25 -> 18 | N25: =F25+J25 -> 16 | O25: =G25+K25 -> 2 | P25: =IF(M25=0,0,N25/M25) -> 0.88888889 | U25: 2 | Z25: =SUM(R25:Y25) -> 2 | AA25: Scope to be clarify with EACOP and CPP headoffice | AC25: =COUNTIFS('[1]Exported from SC (10)'!$X:$X,$B25,'[1]Exported from SC (10)'!$J:$J,"Static Test") -> #VALUE! | AD25: =E25-AC25 -> #VALUE!
A26: 10 | B26: PS4-60-56 | C26: Fuel Conditioning Module PS4-60-UZ-8900A | D26: E/I | E26: =COUNTIFS('Exported from SC '!$X:$X,$B26,'Exported from SC '!$J:$J,"Static Test") -> 10 | F26: =COUNTIFS('Exported from SC '!$X:$X,$B26,'Exported from SC '!$J:$J,"Static Test",'Exported from SC '!$AC:$AC,"Closed") -> 10 | G26: =E26-F26 -> 0 | H26: =IF(E26=0,0,F26/E26) -> 1 | I26: =COUNTIFS('Exported from SC '!$X:$X,$B26,'Exported from SC '!$J:$J,"Conformity Check") -> 15 | J26: =COUNTIFS('Exported from SC '!$X:$X,$B26,'Exported from SC '!$J:$J,"Conformity Check",'Exported from SC '!$AC:$AC,"Closed") -> 11 | K26: =I26-J26 -> 4 | L26: =IF(I26=0,0,J26/I26) -> 0.73333333 | M26: =E26+I26 -> 25 | N26: =F26+J26 -> 21 | O26: =G26+K26 -> 4 | P26: =IF(M26=0,0,N26/M26) -> 0.84 | X26: 4 | Z26: =SUM(R26:Y26) -> 4 | AC26: =COUNTIFS('[1]Exported from SC (10)'!$X:$X,$B26,'[1]Exported from SC (10)'!$J:$J,"Static Test") -> #VALUE! | AD26: =E26-AC26 -> #VALUE!
A27: 11 | B27: PS4-60-58 | C27: Fuel Conditioning Module PS4-60-UZ-8900B | D27: E/I | E27: =COUNTIFS('Exported from SC '!$X:$X,$B27,'Exported from SC '!$J:$J,"Static Test") -> 10 | F27: =COUNTIFS('Exported from SC '!$X:$X,$B27,'Exported from SC '!$J:$J,"Static Test",'Exported from SC '!$AC:$AC,"Closed") -> 10 | G27: =E27-F27 -> 0 | H27: =IF(E27=0,0,F27/E27) -> 1 | I27: =COUNTIFS('Exported from SC '!$X:$X,$B27,'Exported from SC '!$J:$J,"Conformity Check") -> 15 | J27: =COUNTIFS('Exported from SC '!$X:$X,$B27,'Exported from SC '!$J:$J,"Conformity Check",'Exported from SC '!$AC:$AC,"Closed") -> 11 | K27: =I27-J27 -> 4 | L27: =IF(I27=0,0,J27/I27) -> 0.73333333 | M27: =E27+I27 -> 25 | N27: =F27+J27 -> 21 | O27: =G27+K27 -> 4 | P27: =IF(M27=0,0,N27/M27) -> 0.84 | X27: 4 | Z27: =SUM(R27:Y27) -> 4 | AC27: =COUNTIFS('[1]Exported from SC (10)'!$X:$X,$B27,'[1]Exported from SC (10)'!$J:$J,"Static Test") -> #VALUE! | AD27: =E27-AC27 -> #VALUE!
A28: 12 | B28: PS4-60-57 | C28: Fuel Conditioning Module PS4-60-UZ-8900A (UCP) | D28: E/I/T | E28: =COUNTIFS('Exported from SC '!$X:$X,$B28,'Exported from SC '!$J:$J,"Static Test") -> 17 | F28: =COUNTIFS('Exported from SC '!$X:$X,$B28,'Exported from SC '!$J:$J,"Static Test",'Exported from SC '!$AC:$AC,"Closed") -> 16 | G28: =E28-F28 -> 1 | H28: =IF(E28=0,0,F28/E28) -> 0.94117647 | I28: =COUNTIFS('Exported from SC '!$X:$X,$B28,'Exported from SC '!$J:$J,"Conformity Check") -> 17 | J28: =COUNTIFS('Exported from SC '!$X:$X,$B28,'Exported from SC '!$J:$J,"Conformity Check",'Exported from SC '!$AC:$AC,"Closed") -> 16 | K28: =I28-J28 -> 1 | L28: =IF(I28=0,0,J28/I28) -> 0.94117647 | M28: =E28+I28 -> 34 | N28: =F28+J28 -> 32 | O28: =G28+K28 -> 2 | P28: =IF(M28=0,0,N28/M28) -> 0.94117647 | U28: 2 | Z28: =SUM(R28:Y28) -> 2 | AA28: Scope to be clarify with EACOP and CPP headoffice | AC28: =COUNTIFS('[1]Exported from SC (10)'!$X:$X,$B28,'[1]Exported from SC (10)'!$J:$J,"Static Test") -> #VALUE! | AD28: =E28-AC28 -> #VALUE!
A29: 13 | B29: PS4-60-59 | C29: Fuel Conditioning Module PS4-60-UZ-8900B (UCP) | D29: E/I/T | E29: =COUNTIFS('Exported from SC '!$X:$X,$B29,'Exported from SC '!$J:$J,"Static Test") -> 17 | F29: =COUNTIFS('Exported from SC '!$X:$X,$B29,'Exported from SC '!$J:$J,"Static Test",'Exported from SC '!$AC:$AC,"Closed") -> 16 | G29: =E29-F29 -> 1 | H29: =IF(E29=0,0,F29/E29) -> 0.94117647 | I29: =COUNTIFS('Exported from SC '!$X:$X,$B29,'Exported from SC '!$J:$J,"Conformity Check") -> 17 | J29: =COUNTIFS('Exported from SC '!$X:$X,$B29,'Exported from SC '!$J:$J,"Conformity Check",'Exported from SC '!$AC:$AC,"Closed") -> 16 | K29: =I29-J29 -> 1 | L29: =IF(I29=0,0,J29/I29) -> 0.94117647 | M29: =E29+I29 -> 34 | N29: =F29+J29 -> 32 | O29: =G29+K29 -> 2 | P29: =IF(M29=0,0,N29/M29) -> 0.94117647 | U29: 2 | Z29: =SUM(R29:Y29) -> 2 | AA29: Scope to be clarify with EACOP and CPP headoffice | AC29: =COUNTIFS('[1]Exported from SC (10)'!$X:$X,$B29,'[1]Exported from SC (10)'!$J:$J,"Static Test") -> #VALUE! | AD29: =E29-AC29 -> #VALUE!
A30: 14 | B30: PS4-60-02 | C30: Power Gen Package A (UCP) | D30: E/I | E30: =COUNTIFS('Exported from SC '!$X:$X,$B30,'Exported from SC '!$J:$J,"Static Test") -> 31 | F30: =COUNTIFS('Exported from SC '!$X:$X,$B30,'Exported from SC '!$J:$J,"Static Test",'Exported from SC '!$AC:$AC,"Closed") -> 31 | G30: =E30-F30 -> 0 | H30: =IF(E30=0,0,F30/E30) -> 1 | I30: =COUNTIFS('Exported from SC '!$X:$X,$B30,'Exported from SC '!$J:$J,"Conformity Check") -> 36 | J30: =COUNTIFS('Exported from SC '!$X:$X,$B30,'Exported from SC '!$J:$J,"Conformity Check",'Exported from SC '!$AC:$AC,"Closed") -> 36 | K30: =I30-J30 -> 0 | L30: =IF(I30=0,0,J30/I30) -> 1 | M30: =E30+I30 -> 67 | N30: =F30+J30 -> 67 | O30: =G30+K30 -> 0 | P30: =IF(M30=0,0,N30/M30) -> 1 | Z30: =SUM(R30:Y30) -> 0 | AC30: =COUNTIFS('[1]Exported from SC (10)'!$X:$X,$B30,'[1]Exported from SC (10)'!$J:$J,"Static Test") -> #VALUE! | AD30: =E30-AC30 -> #VALUE!
A31: 15 | B31: PS4-60-05 | C31: Power Gen Package B (UCP) | D31: E/I/T | E31: =COUNTIFS('Exported from SC '!$X:$X,$B31,'Exported from SC '!$J:$J,"Static Test") -> 35 | F31: =COUNTIFS('Exported from SC '!$X:$X,$B31,'Exported from SC '!$J:$J,"Static Test",'Exported from SC '!$AC:$AC,"Closed") -> 32 | G31: =E31-F31 -> 3 | H31: =IF(E31=0,0,F31/E31) -> 0.91428571 | I31: =COUNTIFS('Exported from SC '!$X:$X,$B31,'Exported from SC '!$J:$J,"Conformity Check") -> 40 | J31: =COUNTIFS('Exported from SC '!$X:$X,$B31,'Exported from SC '!$J:$J,"Conformity Check",'Exported from SC '!$AC:$AC,"Closed") -> 36 | K31: =I31-J31 -> 4 | L31: =IF(I31=0,0,J31/I31) -> 0.9 | M31: =E31+I31 -> 75 | N31: =F31+J31 -> 68 | O31: =G31+K31 -> 7 | P31: =IF(M31=0,0,N31/M31) -> 0.90666667 | U31: 7 | Z31: =SUM(R31:Y31) -> 7 | AA31: Scope to be clarify with EACOP and CPP headoffice | AC31: =COUNTIFS('[1]Exported from SC (10)'!$X:$X,$B31,'[1]Exported from SC (10)'!$J:$J,"Static Test") -> #VALUE! | AD31: =E31-AC31 -> #VALUE!
A32: 16 | B32: PS4-60-03 | C32: Power Gen Package A Generator Auxiliary MCCs & DBs | D32: E/I/T | E32: =COUNTIFS('Exported from SC '!$X:$X,$B32,'Exported from SC '!$J:$J,"Static Test") -> 12 | F32: =COUNTIFS('Exported from SC '!$X:$X,$B32,'Exported from SC '!$J:$J,"Static Test",'Exported from SC '!$AC:$AC,"Closed") -> 9 | G32: =E32-F32 -> 3 | H32: =IF(E32=0,0,F32/E32) -> 0.75 | I32: =COUNTIFS('Exported from SC '!$X:$X,$B32,'Exported from SC '!$J:$J,"Conformity Check") -> 12 | J32: =COUNTIFS('Exported from SC '!$X:$X,$B32,'Exported from SC '!$J:$J,"Conformity Check",'Exported from SC '!$AC:$AC,"Closed") -> 8 | K32: =I32-J32 -> 4 | L32: =IF(I32=0,0,J32/I32) -> 0.66666667 | M32: =E32+I32 -> 24 | N32: =F32+J32 -> 17 | O32: =G32+K32 -> 7 | P32: =IF(M32=0,0,N32/M32) -> 0.70833333 | U32: 6 | Z32: =SUM(R32:Y32) -> 6 | AA32: Scope to be clarify with EACOP and CPP headoffice | AC32: =COUNTIFS('[1]Exported from SC (10)'!$X:$X,$B32,'[1]Exported from SC (10)'!$J:$J,"Static Test") -> #VALUE! | AD32: =E32-AC32 -> #VALUE!
A33: 17 | B33: PS4-60-06 | C33: Power Gen Package B Generator Auxiliary MCCs & DBs | D33: E/I/T | E33: =COUNTIFS('Exported from SC '!$X:$X,$B33,'Exported from SC '!$J:$J,"Static Test") -> 11 | F33: =COUNTIFS('Exported from SC '!$X:$X,$B33,'Exported from SC '!$J:$J,"Static Test",'Exported from SC '!$AC:$AC,"Closed") -> 8 | G33: =E33-F33 -> 3 | H33: =IF(E33=0,0,F33/E33) -> 0.72727273 | I33: =COUNTIFS('Exported from SC '!$X:$X,$B33,'Exported from SC '!$J:$J,"Conformity Check") -> 11 | J33: =COUNTIFS('Exported from SC '!$X:$X,$B33,'Exported from SC '!$J:$J,"Conformity Check",'Exported from SC '!$AC:$AC,"Closed") -> 8 | K33: =I33-J33 -> 3 | L33: =IF(I33=0,0,J33/I33) -> 0.72727273 | M33: =E33+I33 -> 22 | N33: =F33+J33 -> 16 | O33: =G33+K33 -> 6 | P33: =IF(M33=0,0,N33/M33) -> 0.72727273 | U33: 6 | Z33: =SUM(R33:Y33) -> 6 | AA33: Scope to be clarify with EACOP and CPP headoffice | AC33: =COUNTIFS('[1]Exported from SC (10)'!$X:$X,$B33,'[1]Exported from SC (10)'!$J:$J,"Static Test") -> #VALUE! | AD33: =E33-AC33 -> #VALUE!
A34: 18 | B34: PS4-60-35 | C34: Injector Tip Cooling Module A | D34: E/I | E34: =COUNTIFS('Exported from SC '!$X:$X,$B34,'Exported from SC '!$J:$J,"Static Test") -> 3 | F34: =COUNTIFS('Exported from SC '!$X:$X,$B34,'Exported from SC '!$J:$J,"Static Test",'Exported from SC '!$AC:$AC,"Closed") -> 3 | G34: =E34-F34 -> 0 | H34: =IF(E34=0,0,F34/E34) -> 1 | I34: =COUNTIFS('Exported from SC '!$X:$X,$B34,'Exported from SC '!$J:$J,"Conformity Check") -> 9 | J34: =COUNTIFS('Exported from SC '!$X:$X,$B34,'Exported from SC '!$J:$J,"Conformity Check",'Exported from SC '!$AC:$AC,"Closed") -> 9 | K34: =I34-J34 -> 0 | L34: =IF(I34=0,0,J34/I34) -> 1 | M34: =E34+I34 -> 12 | N34: =F34+J34 -> 12 | O34: =G34+K34 -> 0 | P34: =IF(M34=0,0,N34/M34) -> 1 | Z34: =SUM(R34:Y34) -> 0 | AC34: =COUNTIFS('[1]Exported from SC (10)'!$X:$X,$B34,'[1]Exported from SC (10)'!$J:$J,"Static Test") -> #VALUE! | AD34: =E34-AC34 -> #VALUE!
A35: 19 | B35: PS4-60-36 | C35: Injector Tip Cooling Module B | D35: E/I | E35: =COUNTIFS('Exported from SC '!$X:$X,$B35,'Exported from SC '!$J:$J,"Static Test") -> 3 | F35: =COUNTIFS('Exported from SC '!$X:$X,$B35,'Exported from SC '!$J:$J,"Static Test",'Exported from SC '!$AC:$AC,"Closed") -> 3 | G35: =E35-F35 -> 0 | H35: =IF(E35=0,0,F35/E35) -> 1 | I35: =COUNTIFS('Exported from SC '!$X:$X,$B35,'Exported from SC '!$J:$J,"Conformity Check") -> 9 | J35: =COUNTIFS('Exported from SC '!$X:$X,$B35,'Exported from SC '!$J:$J,"Conformity Check",'Exported from SC '!$AC:$AC,"Closed") -> 9 | K35: =I35-J35 -> 0 | L35: =IF(I35=0,0,J35/I35) -> 1 | M35: =E35+I35 -> 12 | N35: =F35+J35 -> 12 | O35: =G35+K35 -> 0 | P35: =IF(M35=0,0,N35/M35) -> 1 | Z35: =SUM(R35:Y35) -> 0 | AC35: =COUNTIFS('[1]Exported from SC (10)'!$X:$X,$B35,'[1]Exported from SC (10)'!$J:$J,"Static Test") -> #VALUE! | AD35: =E35-AC35 -> #VALUE!
A36: 20 | B36: PS4-60-22 | C36: Power Gen Master UCP | D36: E/I/T | E36: =COUNTIFS('Exported from SC '!$X:$X,$B36,'Exported from SC '!$J:$J,"Static Test") -> 53 | F36: =COUNTIFS('Exported from SC '!$X:$X,$B36,'Exported from SC '!$J:$J,"Static Test",'Exported from SC '!$AC:$AC,"Closed") -> 37 | G36: =E36-F36 -> 16 | H36: =IF(E36=0,0,F36/E36) -> 0.69811321 | I36: =COUNTIFS('Exported from SC '!$X:$X,$B36,'Exported from SC '!$J:$J,"Conformity Check") -> 64 | J36: =COUNTIFS('Exported from SC '!$X:$X,$B36,'Exported from SC '!$J:$J,"Conformity Check",'Exported from SC '!$AC:$AC,"Closed") -> 34 | K36: =I36-J36 -> 30 | L36: =IF(I36=0,0,J36/I36) -> 0.53125 | M36: =E36+I36 -> 117 | N36: =F36+J36 -> 71 | O36: =G36+K36 -> 46 | P36: =IF(M36=0,0,N36/M36) -> 0.60683761 | U36: 42 | Z36: =SUM(R36:Y36) -> 42 | AA36: Scope to be clarify with EACOP and CPP headoffice | AC36: =COUNTIFS('[1]Exported from SC (10)'!$X:$X,$B36,'[1]Exported from SC (10)'!$J:$J,"Static Test") -> #VALUE! | AD36: =E36-AC36 -> #VALUE!
A37: 21 | B37: PS4-71-23 | C37: Diesel Fuel Pre Pressure Module (UCP) | D37: E/I/T | E37: =COUNTIFS('Exported from SC '!$X:$X,$B37,'Exported from SC '!$J:$J,"Static Test") -> 11 | F37: =COUNTIFS('Exported from SC '!$X:$X,$B37,'Exported from SC '!$J:$J,"Static Test",'Exported from SC '!$AC:$AC,"Closed") -> 10 | G37: =E37-F37 -> 1 | H37: =IF(E37=0,0,F37/E37) -> 0.90909091 | I37: =COUNTIFS('Exported from SC '!$X:$X,$B37,'Exported from SC '!$J:$J,"Conformity Check") -> 15 | J37: =COUNTIFS('Exported from SC '!$X:$X,$B37,'Exported from SC '!$J:$J,"Conformity Check",'Exported from SC '!$AC:$AC,"Closed") -> 5 | K37: =I37-J37 -> 10 | L37: =IF(I37=0,0,J37/I37) -> 0.33333333 | M37: =E37+I37 -> 26 | N37: =F37+J37 -> 15 | O37: =G37+K37 -> 11 | P37: =IF(M37=0,0,N37/M37) -> 0.57692308 | U37: 2 | Z37: =SUM(R37:Y37) -> 2 | AA37: Scope to be clarify with EACOP and CPP headoffice | AC37: =COUNTIFS('[1]Exported from SC (10)'!$X:$X,$B37,'[1]Exported from SC (10)'!$J:$J,"Static Test") -> #VALUE! | AD37: =E37-AC37 -> #VALUE!
A38: 22 | B38: PS4-60-70 | C38: Engine A Cooling system | D38: E/I | E38: =COUNTIFS('Exported from SC '!$X:$X,$B38,'Exported from SC '!$J:$J,"Static Test") -> 6 | F38: =COUNTIFS('Exported from SC '!$X:$X,$B38,'Exported from SC '!$J:$J,"Static Test",'Exported from SC '!$AC:$AC,"Closed") -> 6 | G38: =E38-F38 -> 0 | H38: =IF(E38=0,0,F38/E38) -> 1 | I38: =COUNTIFS('Exported from SC '!$X:$X,$B38,'Exported from SC '!$J:$J,"Conformity Check") -> 18 | J38: =COUNTIFS('Exported from SC '!$X:$X,$B38,'Exported from SC '!$J:$J,"Conformity Check",'Exported from SC '!$AC:$AC,"Closed") -> 18 | K38: =I38-J38 -> 0 | L38: =IF(I38=0,0,J38/I38) -> 1 | M38: =E38+I38 -> 24 | N38: =F38+J38 -> 24 | O38: =G38+K38 -> 0 | P38: =IF(M38=0,0,N38/M38) -> 1 | Z38: =SUM(R38:Y38) -> 0 | AC38: =COUNTIFS('[1]Exported from SC (10)'!$X:$X,$B38,'[1]Exported from SC (10)'!$J:$J,"Static Test") -> #VALUE! | AD38: =E38-AC38 -> #VALUE!
A39: 23 | B39: PS4-60-71 | C39: Engine B Cooling system | D39: E/I | E39: =COUNTIFS('Exported from SC '!$X:$X,$B39,'Exported from SC '!$J:$J,"Static Test") -> 6 | F39: =COUNTIFS('Exported from SC '!$X:$X,$B39,'Exported from SC '!$J:$J,"Static Test",'Exported from SC '!$AC:$AC,"Closed") -> 6 | G39: =E39-F39 -> 0 | H39: =IF(E39=0,0,F39/E39) -> 1 | I39: =COUNTIFS('Exported from SC '!$X:$X,$B39,'Exported from SC '!$J:$J,"Conformity Check") -> 18 | J39: =COUNTIFS('Exported from SC '!$X:$X,$B39,'Exported from SC '!$J:$J,"Conformity Check",'Exported from SC '!$AC:$AC,"Closed") -> 18 | K39: =I39-J39 -> 0 | L39: =IF(I39=0,0,J39/I39) -> 1 | M39: =E39+I39 -> 24 | N39: =F39+J39 -> 24 | O39: =G39+K39 -> 0 | P39: =IF(M39=0,0,N39/M39) -> 1 | Z39: =SUM(R39:Y39) -> 0 | AC39: =COUNTIFS('[1]Exported from SC (10)'!$X:$X,$B39,'[1]Exported from SC (10)'!$J:$J,"Static Test") -> #VALUE! | AD39: =E39-AC39 -> #VALUE!
A40: 24 | B40: PS4-60-01 | C40: Power Generation Package A | D40: E/I | E40: =COUNTIFS('Exported from SC '!$X:$X,$B40,'Exported from SC '!$J:$J,"Static Test") -> 86 | F40: =COUNTIFS('Exported from SC '!$X:$X,$B40,'Exported from SC '!$J:$J,"Static Test",'Exported from SC '!$AC:$AC,"Closed") -> 84 | G40: =E40-F40 -> 2 | H40: =IF(E40=0,0,F40/E40) -> 0.97674419 | I40: =COUNTIFS('Exported from SC '!$X:$X,$B40,'Exported from SC '!$J:$J,"Conformity Check") -> 112 | J40: =COUNTIFS('Exported from SC '!$X:$X,$B40,'Exported from SC '!$J:$J,"Conformity Check",'Exported from SC '!$AC:$AC,"Closed") -> 94 | K40: =I40-J40 -> 18 | L40: =IF(I40=0,0,J40/I40) -> 0.83928571 | M40: =E40+I40 -> 198 | N40: =F40+J40 -> 178 | O40: =G40+K40 -> 20 | P40: =IF(M40=0,0,N40/M40) -> 0.8989899 | V40: 3 | Y40: 2 | Z40: =SUM(R40:Y40) -> 5 | AA40: 1.Transformer top up oil to be completed , 2.CCP1 to be finalise cable tray support in Transformer wall | AC40: =COUNTIFS('[1]Exported from SC (10)'!$X:$X,$B40,'[1]Exported from SC (10)'!$J:$J,"Static Test") -> #VALUE! | AD40: =E40-AC40 -> #VALUE!
A41: 25 | B41: PS4-60-04 | C41: Power Generation Package B | D41: E/I | E41: =COUNTIFS('Exported from SC '!$X:$X,$B41,'Exported from SC '!$J:$J,"Static Test") -> 62 | F41: =COUNTIFS('Exported from SC '!$X:$X,$B41,'Exported from SC '!$J:$J,"Static Test",'Exported from SC '!$AC:$AC,"Closed") -> 59 | G41: =E41-F41 -> 3 | H41: =IF(E41=0,0,F41/E41) -> 0.9516129 | I41: =COUNTIFS('Exported from SC '!$X:$X,$B41,'Exported from SC '!$J:$J,"Conformity Check") -> 80 | J41: =COUNTIFS('Exported from SC '!$X:$X,$B41,'Exported from SC '!$J:$J,"Conformity Check",'Exported from SC '!$AC:$AC,"Closed") -> 75 | K41: =I41-J41 -> 5 | L41: =IF(I41=0,0,J41/I41) -> 0.9375 | M41: =E41+I41 -> 142 | N41: =F41+J41 -> 134 | O41: =G41+K41 -> 8 | P41: =IF(M41=0,0,N41/M41) -> 0.94366197 | V41: 3 | W41: 2 | Y41: 2 | Z41: =SUM(R41:Y41) -> 7 | AA41: 1.SRN-02017 ETA 29 0ctober(140 Mtr for Genset-B (6T X 0.75 IS/OS FL RTD) 2..Transformer top up oil to be completed , 3.CCP1 to be finalise cable tray support in Transformer wall | AC41: =COUNTIFS('[1]Exported from SC (10)'!$X:$X,$B41,'[1]Exported from SC (10)'!$J:$J,"Static Test") -> #VALUE! | AD41: =E41-AC41 -> #VALUE!
A42: 26 | B42: PS4-71-22 | C42: Diesel Fuel Pre Pressure Module | D42: E/I | E42: =COUNTIFS('Exported from SC '!$X:$X,$B42,'Exported from SC '!$J:$J,"Static Test") -> 15 | F42: =COUNTIFS('Exported from SC '!$X:$X,$B42,'Exported from SC '!$J:$J,"Static Test",'Exported from SC '!$AC:$AC,"Closed") -> 15 | G42: =E42-F42 -> 0 | H42: =IF(E42=0,0,F42/E42) -> 1 | I42: =COUNTIFS('Exported from SC '!$X:$X,$B42,'Exported from SC '!$J:$J,"Conformity Check") -> 22 | J42: =COUNTIFS('Exported from SC '!$X:$X,$B42,'Exported from SC '!$J:$J,"Conformity Check",'Exported from SC '!$AC:$AC,"Closed") -> 22 | K42: =I42-J42 -> 0 | L42: =IF(I42=0,0,J42/I42) -> 1 | M42: =E42+I42 -> 37 | N42: =F42+J42 -> 37 | O42: =G42+K42 -> 0 | P42: =IF(M42=0,0,N42/M42) -> 1 | Z42: =SUM(R42:Y42) -> 0 | AC42: =COUNTIFS('[1]Exported from SC (10)'!$X:$X,$B42,'[1]Exported from SC (10)'!$J:$J,"Static Test") -> #VALUE! | AD42: =E42-AC42 -> #VALUE!
A43: 27 | B43: PS4-61-04 | C43: PS4-61-04 - 0.4kV Switchboard Power Generator Building (PS4-61-IK-0003) | D43: E/I | E43: =COUNTIFS('Exported from SC '!$X:$X,$B43,'Exported from SC '!$J:$J,"Static Test") -> 53 | F43: =COUNTIFS('Exported from SC '!$X:$X,$B43,'Exported from SC '!$J:$J,"Static Test",'Exported from SC '!$AC:$AC,"Closed") -> 50 | G43: =E43-F43 -> 3 | H43: =IF(E43=0,0,F43/E43) -> 0.94339623 | I43: =COUNTIFS('Exported from SC '!$X:$X,$B43,'Exported from SC '!$J:$J,"Conformity Check") -> 63 | J43: =COUNTIFS('Exported from SC '!$X:$X,$B43,'Exported from SC '!$J:$J,"Conformity Check",'Exported from SC '!$AC:$AC,"Closed") -> 14 | K43: =I43-J43 -> 49 | L43: =IF(I43=0,0,J43/I43) -> 0.22222222 | M43: =E43+I43 -> 116 | N43: =F43+J43 -> 64 | O43: =G43+K43 -> 52 | P43: =IF(M43=0,0,N43/M43) -> 0.55172414 | S43: 36 | Z43: =SUM(R43:Y43) -> 36 | AA43: Cable lugs (500 SQ) mm hole not matching to SWG bus-bar bolt (Hole big size) | AC43: =COUNTIFS('[1]Exported from SC (10)'!$X:$X,$B43,'[1]Exported from SC (10)'!$J:$J,"Static Test") -> #VALUE! | AD43: =E43-AC43 -> #VALUE!
A44: 28 | B44: PS4-06-02 | C44: AC UPS - Power Generator Building | D44: E/I | E44: =COUNTIFS('Exported from SC '!$X:$X,$B44,'Exported from SC '!$J:$J,"Static Test") -> 26 | F44: =COUNTIFS('Exported from SC '!$X:$X,$B44,'Exported from SC '!$J:$J,"Static Test",'Exported from SC '!$AC:$AC,"Closed") -> 19 | G44: =E44-F44 -> 7 | H44: =IF(E44=0,0,F44/E44) -> 0.73076923 | I44: =COUNTIFS('Exported from SC '!$X:$X,$B44,'Exported from SC '!$J:$J,"Conformity Check") -> 32 | J44: =COUNTIFS('Exported from SC '!$X:$X,$B44,'Exported from SC '!$J:$J,"Conformity Check",'Exported from SC '!$AC:$AC,"Closed") -> 20 | K44: =I44-J44 -> 12 | L44: =IF(I44=0,0,J44/I44) -> 0.625 | M44: =E44+I44 -> 58 | N44: =F44+J44 -> 39 | O44: =G44+K44 -> 19 | P44: =IF(M44=0,0,N44/M44) -> 0.67241379 | Z44: =SUM(R44:Y44) -> 0 | AC44: =COUNTIFS('[1]Exported from SC (10)'!$X:$X,$B44,'[1]Exported from SC (10)'!$J:$J,"Static Test") -> #VALUE! | AD44: =E44-AC44 -> #VALUE!
E45: =SUM(E17:E44) -> 532 | F45: =SUM(F17:F44) -> 452 | G45: =SUM(G17:G44) -> 80 | H45: =SUM(H17:H44) -> 23.26305 | I45: =SUM(I17:I44) -> 810 | J45: =SUM(J17:J44) -> 629 | K45: =SUM(K17:K44) -> 181 | M45: =SUM(M17:M44) -> 1342 | N45: =SUM(N17:N43) -> 1042 | O45: =SUM(O17:O43) -> 242 | P45: =N45/M45 -> 0.77645306 | R45: =SUM(R17:R43) -> 65 | S45: =SUM(S17:S43) -> 36 | T45: =SUM(T17:T43) -> 2 | U45: =SUM(U17:U43) -> 71 | V45: =SUM(V17:V43) -> 6 | W45: =SUM(W17:W43) -> 2 | X45: =SUM(X17:X43) -> 8 | Y45: =SUM(Y17:Y43) -> 4 | Z45: =SUM(R45:Y45) -> 194

Sheet Priority-2 
B1: CPP AGI - E/I/T Static & Conformity Closure Summary by Subsystem
B2: Source: uploaded ovTasks_TestsPlanned_1369 (21).xlsx | Updated all 44 workbook subsystems | Company filter: CPP AGI | Disciplines combined: Electrical + Instrumentation + Telecom | Closed = Task State = Closed | Overall = Static Test + Conformity Check.
B4: Subsystem IDs | C4: Static Total | D4: Static Balance | E4: Static Closed % | F4: Conformity Total | G4: Conformity Closed | H4: Conformity Balance | I4: Conformity Closed % | J4: Overall Total | K4: Overall Closed | L4: Overall Closed %
B5: =COUNTA(B17:B39) -> 23 | C5: =SUM(D17:D39) -> 461 | D5: =C5-#REF! -> #REF! | E5: =IF(C5=0,0,#REF!/C5) -> #REF! | F5: =SUM(H17:H39) -> 610 | G5: =SUM(I17:I39) -> 87 | H5: =F5-G5 -> 523 | I5: =IF(F5=0,0,G5/F5) -> 0.14262295 | J5: =C5+F5 -> 1071 | K5: =#REF!+G5 -> #REF! | L5: =IF(J5=0,0,K5/J5) -> #REF!
B8: Combined Summary
B9: Group | C9: Static Total | D9: Static Balance | E9: Static Closed % | F9: Conformity Total | G9: Conformity Closed | H9: Conformity Balance | I9: Conformity Closed % | J9: Overall Total | K9: Overall Closed | L9: Overall Balance | M9: Overall Closed %
B10: All E/I/T Disciplines | C10: =SUM(D17:D39) -> 461 | D10: =C10-#REF! -> #REF! | E10: =IF(C10=0,0,#REF!/C10) -> #REF! | F10: =SUM(H17:H39) -> 610 | G10: =SUM(I17:I39) -> 87 | H10: =F10-G10 -> 523 | I10: =IF(F10=0,0,G10/F10) -> 0.14262295 | J10: =C10+F10 -> 1071 | K10: =#REF!+G10 -> #REF! | L10: =J10-K10 -> #REF! | M10: =IF(J10=0,0,K10/J10) -> #REF!
A15: Priority-01 C & D | P15: We cannot Close the below ITR's Right now
A16: Sl NO | B16: Subsystem ID | C16: Subsystem Description | D16: Static Total | E16: Static Closed | F16: Static Balance | G16: Static Closed % | H16: Conformity Total | I16: Conformity Closed | J16: Conformity Balance | K16: Conformity Closed % | L16: Overall Total | M16: Overall Closed | N16: Overall Balance | O16: Overall Closed % | P16: CAT6/MODbus/Fiber | Q16: Transformer wall (Cables) | R16: Transformer | S16: Duplex filter JB & PIT Not find
A17: 1 | B17: PS4-60-07 | C17: Power Generation Package C | D17: =COUNTIFS('Exported from SC '!$X:$X,$B17,'Exported from SC '!$J:$J,"Static Test") -> 62 | E17: =COUNTIFS('Exported from SC '!$X:$X,$B17,'Exported from SC '!$J:$J,"Static Test",'Exported from SC '!$AC:$AC,"Closed") -> 56 | F17: =D17-E17 -> 6 | G17: =IF(D17=0,0,E17/D17) -> 0.90322581 | H17: =COUNTIFS('Exported from SC '!$X:$X,$B17,'Exported from SC '!$J:$J,"Conformity Check") -> 80 | I17: =COUNTIFS('Exported from SC '!$X:$X,$B17,'Exported from SC '!$J:$J,"Conformity Check",'Exported from SC '!$AC:$AC,"Closed") -> 21 | J17: =H17-I17 -> 59 | K17: =IF(H17=0,0,I17/H17) -> 0.2625 | L17: =D17+H17 -> 142 | M17: =E17+I17 -> 77 | N17: =F17+J17 -> 65 | O17: =IF(L17=0,0,M17/L17) -> 0.54225352
A18: 2 | B18: PS4-60-08 | C18: Power Gen Package C (UCP) | D18: =COUNTIFS('Exported from SC '!$X:$X,$B18,'Exported from SC '!$J:$J,"Static Test") -> 35 | E18: =COUNTIFS('Exported from SC '!$X:$X,$B18,'Exported from SC '!$J:$J,"Static Test",'Exported from SC '!$AC:$AC,"Closed") -> 27 | F18: =D18-E18 -> 8 | G18: =IF(D18=0,0,E18/D18) -> 0.77142857 | H18: =COUNTIFS('Exported from SC '!$X:$X,$B18,'Exported from SC '!$J:$J,"Conformity Check") -> 40 | I18: =COUNTIFS('Exported from SC '!$X:$X,$B18,'Exported from SC '!$J:$J,"Conformity Check",'Exported from SC '!$AC:$AC,"Closed") -> 0 | J18: =H18-I18 -> 40 | K18: =IF(H18=0,0,I18/H18) -> 0 | L18: =D18+H18 -> 75 | M18: =E18+I18 -> 27 | N18: =F18+J18 -> 48 | O18: =IF(L18=0,0,M18/L18) -> 0.36
A19: 3 | B19: PS4-60-09 | C19: Power Gen Package C Generator Auxiliary MCCs & DBs | D19: =COUNTIFS('Exported from SC '!$X:$X,$B19,'Exported from SC '!$J:$J,"Static Test") -> 12 | E19: =COUNTIFS('Exported from SC '!$X:$X,$B19,'Exported from SC '!$J:$J,"Static Test",'Exported from SC '!$AC:$AC,"Closed") -> 9 | F19: =D19-E19 -> 3 | G19: =IF(D19=0,0,E19/D19) -> 0.75 | H19: =COUNTIFS('Exported from SC '!$X:$X,$B19,'Exported from SC '!$J:$J,"Conformity Check") -> 12 | I19: =COUNTIFS('Exported from SC '!$X:$X,$B19,'Exported from SC '!$J:$J,"Conformity Check",'Exported from SC '!$AC:$AC,"Closed") -> 5 | J19: =H19-I19 -> 7 | K19: =IF(H19=0,0,I19/H19) -> 0.41666667 | L19: =D19+H19 -> 24 | M19: =E19+I19 -> 14 | N19: =F19+J19 -> 10 | O19: =IF(L19=0,0,M19/L19) -> 0.58333333
A20: 4 | B20: PS4-60-10 | C20: Power Generation Package D | D20: =COUNTIFS('Exported from SC '!$X:$X,$B20,'Exported from SC '!$J:$J,"Static Test") -> 76 | E20: =COUNTIFS('Exported from SC '!$X:$X,$B20,'Exported from SC '!$J:$J,"Static Test",'Exported from SC '!$AC:$AC,"Closed") -> 66 | F20: =D20-E20 -> 10 | G20: =IF(D20=0,0,E20/D20) -> 0.86842105 | H20: =COUNTIFS('Exported from SC '!$X:$X,$B20,'Exported from SC '!$J:$J,"Conformity Check") -> 95 | I20: =COUNTIFS('Exported from SC '!$X:$X,$B20,'Exported from SC '!$J:$J,"Conformity Check",'Exported from SC '!$AC:$AC,"Closed") -> 10 | J20: =H20-I20 -> 85 | K20: =IF(H20=0,0,I20/H20) -> 0.10526316 | L20: =D20+H20 -> 171 | M20: =E20+I20 -> 76 | N20: =F20+J20 -> 95 | O20: =IF(L20=0,0,M20/L20) -> 0.44444444
A21: 5 | B21: PS4-60-11 | C21: Power Gen Package D (UCP) | D21: =COUNTIFS('Exported from SC '!$X:$X,$B21,'Exported from SC '!$J:$J,"Static Test") -> 35 | E21: =COUNTIFS('Exported from SC '!$X:$X,$B21,'Exported from SC '!$J:$J,"Static Test",'Exported from SC '!$AC:$AC,"Closed") -> 23 | F21: =D21-E21 -> 12 | G21: =IF(D21=0,0,E21/D21) -> 0.65714286 | H21: =COUNTIFS('Exported from SC '!$X:$X,$B21,'Exported from SC '!$J:$J,"Conformity Check") -> 40 | I21: =COUNTIFS('Exported from SC '!$X:$X,$B21,'Exported from SC '!$J:$J,"Conformity Check",'Exported from SC '!$AC:$AC,"Closed") -> 0 | J21: =H21-I21 -> 40 | K21: =IF(H21=0,0,I21/H21) -> 0 | L21: =D21+H21 -> 75 | M21: =E21+I21 -> 23 | N21: =F21+J21 -> 52 | O21: =IF(L21=0,0,M21/L21) -> 0.30666667
A22: 6 | B22: PS4-60-12 | C22: Power Gen Package D Generator Auxiliary MCCs & DBs | D22: =COUNTIFS('Exported from SC '!$X:$X,$B22,'Exported from SC '!$J:$J,"Static Test") -> 11 | E22: =COUNTIFS('Exported from SC '!$X:$X,$B22,'Exported from SC '!$J:$J,"Static Test",'Exported from SC '!$AC:$AC,"Closed") -> 8 | F22: =D22-E22 -> 3 | G22: =IF(D22=0,0,E22/D22) -> 0.72727273 | H22: =COUNTIFS('Exported from SC '!$X:$X,$B22,'Exported from SC '!$J:$J,"Conformity Check") -> 11 | I22: =COUNTIFS('Exported from SC '!$X:$X,$B22,'Exported from SC '!$J:$J,"Conformity Check",'Exported from SC '!$AC:$AC,"Closed") -> 4 | J22: =H22-I22 -> 7 | K22: =IF(H22=0,0,I22/H22) -> 0.36363636 | L22: =D22+H22 -> 22 | M22: =E22+I22 -> 12 | N22: =F22+J22 -> 10 | O22: =IF(L22=0,0,M22/L22) -> 0.54545455
A23: 7 | B23: PS4-60-37 | C23: Injector Tip Cooling Module C | D23: =COUNTIFS('Exported from SC '!$X:$X,$B23,'Exported from SC '!$J:$J,"Static Test") -> 3 | E23: =COUNTIFS('Exported from SC '!$X:$X,$B23,'Exported from SC '!$J:$J,"Static Test",'Exported from SC '!$AC:$AC,"Closed") -> 3 | F23: =D23-E23 -> 0 | G23: =IF(D23=0,0,E23/D23) -> 1 | H23: =COUNTIFS('Exported from SC '!$X:$X,$B23,'Exported from SC '!$J:$J,"Conformity Check") -> 9 | I23: =COUNTIFS('Exported from SC '!$X:$X,$B23,'Exported from SC '!$J:$J,"Conformity Check",'Exported from SC '!$AC:$AC,"Closed") -> 2 | J23: =H23-I23 -> 7 | K23: =IF(H23=0,0,I23/H23) -> 0.22222222 | L23: =D23+H23 -> 12 | M23: =E23+I23 -> 5 | N23: =F23+J23 -> 7 | O23: =IF(L23=0,0,M23/L23) -> 0.41666667
A24: 8 | B24: PS4-60-38 | C24: Injector Tip Cooling Module D | D24: =COUNTIFS('Exported from SC '!$X:$X,$B24,'Exported from SC '!$J:$J,"Static Test") -> 3 | E24: =COUNTIFS('Exported from SC '!$X:$X,$B24,'Exported from SC '!$J:$J,"Static Test",'Exported from SC '!$AC:$AC,"Closed") -> 3 | F24: =D24-E24 -> 0 | G24: =IF(D24=0,0,E24/D24) -> 1 | H24: =COUNTIFS('Exported from SC '!$X:$X,$B24,'Exported from SC '!$J:$J,"Conformity Check") -> 9 | I24: =COUNTIFS('Exported from SC '!$X:$X,$B24,'Exported from SC '!$J:$J,"Conformity Check",'Exported from SC '!$AC:$AC,"Closed") -> 0 | J24: =H24-I24 -> 9 | K24: =IF(H24=0,0,I24/H24) -> 0 | L24: =D24+H24 -> 12 | M24: =E24+I24 -> 3 | N24: =F24+J24 -> 9 | O24: =IF(L24=0,0,M24/L24) -> 0.25
A25: 9 | B25: PS4-60-44 | C25: Oil Mist Separator Skid PS4-60-VS-9100C | D25: =COUNTIFS('Exported from SC '!$X:$X,$B25,'Exported from SC '!$J:$J,"Static Test") -> 2 | E25: =COUNTIFS('Exported from SC '!$X:$X,$B25,'Exported from SC '!$J:$J,"Static Test",'Exported from SC '!$AC:$AC,"Closed") -> 2 | F25: =D25-E25 -> 0 | G25: =IF(D25=0,0,E25/D25) -> 1 | H25: =COUNTIFS('Exported from SC '!$X:$X,$B25,'Exported from SC '!$J:$J,"Conformity Check") -> 4 | I25: =COUNTIFS('Exported from SC '!$X:$X,$B25,'Exported from SC '!$J:$J,"Conformity Check",'Exported from SC '!$AC:$AC,"Closed") -> 0 | J25: =H25-I25 -> 4 | K25: =IF(H25=0,0,I25/H25) -> 0 | L25: =D25+H25 -> 6 | M25: =E25+I25 -> 2 | N25: =F25+J25 -> 4 | O25: =IF(L25=0,0,M25/L25) -> 0.33333333
A26: 10 | B26: PS4-60-45 | C26: Oil Mist Separator Skid PS4-60-VS-9100D | D26: =COUNTIFS('Exported from SC '!$X:$X,$B26,'Exported from SC '!$J:$J,"Static Test") -> 2 | E26: =COUNTIFS('Exported from SC '!$X:$X,$B26,'Exported from SC '!$J:$J,"Static Test",'Exported from SC '!$AC:$AC,"Closed") -> 2 | F26: =D26-E26 -> 0 | G26: =IF(D26=0,0,E26/D26) -> 1 | H26: =COUNTIFS('Exported from SC '!$X:$X,$B26,'Exported from SC '!$J:$J,"Conformity Check") -> 4 | I26: =COUNTIFS('Exported from SC '!$X:$X,$B26,'Exported from SC '!$J:$J,"Conformity Check",'Exported from SC '!$AC:$AC,"Closed") -> 0 | J26: =H26-I26 -> 4 | K26: =IF(H26=0,0,I26/H26) -> 0 | L26: =D26+H26 -> 6 | M26: =E26+I26 -> 2 | N26: =F26+J26 -> 4 | O26: =IF(L26=0,0,M26/L26) -> 0.33333333
A27: 11 | B27: PS4-60-51 | C27: Lube Oil Separator Module PS4-60-UO-81100C | D27: =COUNTIFS('Exported from SC '!$X:$X,$B27,'Exported from SC '!$J:$J,"Static Test") -> 8 | E27: =COUNTIFS('Exported from SC '!$X:$X,$B27,'Exported from SC '!$J:$J,"Static Test",'Exported from SC '!$AC:$AC,"Closed") -> 7 | F27: =D27-E27 -> 1 | G27: =IF(D27=0,0,E27/D27) -> 0.875 | H27: =COUNTIFS('Exported from SC '!$X:$X,$B27,'Exported from SC '!$J:$J,"Conformity Check") -> 10 | I27: =COUNTIFS('Exported from SC '!$X:$X,$B27,'Exported from SC '!$J:$J,"Conformity Check",'Exported from SC '!$AC:$AC,"Closed") -> 1 | J27: =H27-I27 -> 9 | K27: =IF(H27=0,0,I27/H27) -> 0.1 | L27: =D27+H27 -> 18 | M27: =E27+I27 -> 8 | N27: =F27+J27 -> 10 | O27: =IF(L27=0,0,M27/L27) -> 0.44444444
A28: 12 | B28: PS4-60-52 | C28: Lube Oil Separator Module PS4-60-UO-81100D | D28: =COUNTIFS('Exported from SC '!$X:$X,$B28,'Exported from SC '!$J:$J,"Static Test") -> 8 | E28: =COUNTIFS('Exported from SC '!$X:$X,$B28,'Exported from SC '!$J:$J,"Static Test",'Exported from SC '!$AC:$AC,"Closed") -> 6 | F28: =D28-E28 -> 2 | G28: =IF(D28=0,0,E28/D28) -> 0.75 | H28: =COUNTIFS('Exported from SC '!$X:$X,$B28,'Exported from SC '!$J:$J,"Conformity Check") -> 10 | I28: =COUNTIFS('Exported from SC '!$X:$X,$B28,'Exported from SC '!$J:$J,"Conformity Check",'Exported from SC '!$AC:$AC,"Closed") -> 1 | J28: =H28-I28 -> 9 | K28: =IF(H28=0,0,I28/H28) -> 0.1 | L28: =D28+H28 -> 18 | M28: =E28+I28 -> 7 | N28: =F28+J28 -> 11 | O28: =IF(L28=0,0,M28/L28) -> 0.38888889
... A39: 23 | B39: PS4-71-07 | C39: Crude Fuel Separation Module (UCP) | D39: =COUNTIFS('Exported from SC '!$X:$X,$B39,'Exported from SC '!$J:$J,"Static Test") -> 54 | E39: =COUNTIFS('Exported from SC '!$X:$X,$B39,'Exported from SC '!$J:$J,"Static Test",'Exported from SC '!$AC:$AC,"Closed") -> 48 | F39: =D39-E39 -> 6 | G39: =IF(D39=0,0,E39/D39) -> 0.88888889 | H39: =COUNTIFS('Exported from SC '!$X:$X,$B39,'Exported from SC '!$J:$J,"Conformity Check") -> 60 | I39: =COUNTIFS('Exported from SC '!$X:$X,$B39,'Exported from SC '!$J:$J,"Conformity Check",'Exported from SC '!$AC:$AC,"Closed") -> 2 | J39: =H39-I39 -> 58 | K39: =IF(H39=0,0,I39/H39) -> 0.033333333 | L39: =D39+H39 -> 114 | M39: =E39+I39 -> 50 | N39: =F39+J39 -> 64 | O39: =IF(L39=0,0,M39/L39) -> 0.43859649
D40: =SUM(D17:D39) -> 461 | E40: =SUM(E17:E39) -> 379 | F40: =SUM(F17:F39) -> 82 | G40: =E40/D40 -> 0.82212581 | H40: =SUM(H17:H39) -> 610 | I40: =SUM(I17:I39) -> 87 | J40: =SUM(J17:J39) -> 523 | K40: =I40/H40 -> 0.14262295 | L40: =SUM(L17:L39) -> 1071 | M40: =SUM(M17:M39) -> 466 | N40: =SUM(N17:N39) -> 605 | O40: =M40/L40 -> 0.43510738 | P40: =SUM(P17:P39) -> 0 | Q40: =SUM(Q17:Q39) -> 0 | R40: =SUM(R17:R39) -> 0 | S40: =SUM(S17:S39) -> 0 | T40: =SUM(P40:S40) -> 0

Sheet Priority-EDG
B1: CPP AGI - E/I/T Static & Conformity Closure Summary by Subsystem
B2: Source: uploaded ovTasks_TestsPlanned_1369 (21).xlsx | Updated all 44 workbook subsystems | Company filter: CPP AGI | Disciplines combined: Electrical + Instrumentation + Telecom | Closed = Task State = Closed | Overall = Static Test + Conformity Check.
B4: Subsystem IDs | C4: Static Total | D4: Static Balance | E4: Static Closed % | F4: Conformity Total | G4: Conformity Closed | H4: Conformity Balance | I4: Conformity Closed % | J4: Overall Total | K4: Overall Closed | L4: Overall Closed %
B5: =COUNTA(B17:B18) -> 2 | C5: =SUM(D17:D18) -> 75 | D5: =C5-#REF! -> #REF! | E5: =IF(C5=0,0,#REF!/C5) -> #REF! | F5: =SUM(H17:H18) -> 84 | G5: =SUM(I17:I18) -> 42 | H5: =F5-G5 -> 42 | I5: =IF(F5=0,0,G5/F5) -> 0.5 | J5: =C5+F5 -> 159 | K5: =#REF!+G5 -> #REF! | L5: =IF(J5=0,0,K5/J5) -> #REF!
B8: Combined Summary
B9: Group | C9: Static Total | D9: Static Balance | E9: Static Closed % | F9: Conformity Total | G9: Conformity Closed | H9: Conformity Balance | I9: Conformity Closed % | J9: Overall Total | K9: Overall Closed | L9: Overall Balance | M9: Overall Closed %
B10: All E/I/T Disciplines | C10: =SUM(D17:D18) -> 75 | D10: =C10-#REF! -> #REF! | E10: =IF(C10=0,0,#REF!/C10) -> #REF! | F10: =SUM(H17:H18) -> 84 | G10: =SUM(I17:I18) -> 42 | H10: =F10-G10 -> 42 | I10: =IF(F10=0,0,G10/F10) -> 0.5 | J10: =C10+F10 -> 159 | K10: =#REF!+G10 -> #REF! | L10: =J10-K10 -> #REF! | M10: =IF(J10=0,0,K10/J10) -> #REF!
A15: EDG ITR Status | Q15: ITR Closing ON-Going | S15: We cannot Close the below ITR's Right now
A16: Sl NO | B16: Subsystem ID | C16: Subsystem Description | D16: Static Total | E16: Static Closed | F16: Static Balance | G16: Static Closed % | H16: Conformity Total | I16: Conformity Closed | J16: Conformity Balance | K16: Conformity Closed % | L16: Overall Total ITR | M16: Overall Closed ITR | N16: Overall Balance ITR | O16: Overall Closed % | S16: Cable Gland Not available M25/M32/M40 | T16: Cable Lug 500 Sqmm (Hole Missmatch) | U16: Total
A17: 1 | B17: PS4-05-01 | C17: Emergency Diesel Generator Package | D17: =COUNTIFS('Exported from SC '!$X:$X,$B17,'Exported from SC '!$J:$J,"Static Test") -> 51 | E17: =COUNTIFS('Exported from SC '!$X:$X,$B17,'Exported from SC '!$J:$J,"Static Test",'Exported from SC '!$AC:$AC,"Closed") -> 51 | F17: =D17-E17 -> 0 | G17: =IF(D17=0,0,E17/D17) -> 1 | H17: =COUNTIFS('Exported from SC '!$X:$X,$B17,'Exported from SC '!$J:$J,"Conformity Check") -> 55 | I17: =COUNTIFS('Exported from SC '!$X:$X,$B17,'Exported from SC '!$J:$J,"Conformity Check",'Exported from SC '!$AC:$AC,"Closed") -> 20 | J17: =H17-I17 -> 35 | K17: =IF(H17=0,0,I17/H17) -> 0.36363636 | L17: =D17+H17 -> 106 | M17: =E17+I17 -> 71 | N17: =F17+J17 -> 35 | O17: =IF(L17=0,0,M17/L17) -> 0.66981132 | Q17: =N17-U17 -> 8 | S17: 9 | T17: 18 | U17: =T17+S17 -> 27
A18: 2 | B18: PS4-05-02 | C18: Emergency Diesel Generator Package (UCP) | D18: =COUNTIFS('Exported from SC '!$X:$X,$B18,'Exported from SC '!$J:$J,"Static Test") -> 24 | E18: =COUNTIFS('Exported from SC '!$X:$X,$B18,'Exported from SC '!$J:$J,"Static Test",'Exported from SC '!$AC:$AC,"Closed") -> 23 | F18: =D18-E18 -> 1 | G18: =IF(D18=0,0,E18/D18) -> 0.95833333 | H18: =COUNTIFS('Exported from SC '!$X:$X,$B18,'Exported from SC '!$J:$J,"Conformity Check") -> 29 | I18: =COUNTIFS('Exported from SC '!$X:$X,$B18,'Exported from SC '!$J:$J,"Conformity Check",'Exported from SC '!$AC:$AC,"Closed") -> 22 | J18: =H18-I18 -> 7 | K18: =IF(H18=0,0,I18/H18) -> 0.75862069 | L18: =D18+H18 -> 53 | M18: =E18+I18 -> 45 | N18: =F18+J18 -> 8 | O18: =IF(L18=0,0,M18/L18) -> 0.8490566 | Q18: =N18-U18 -> 7 | S18: 1 | T18: 0 | U18: =T18+S18 -> 1
C19: Total | D19: =SUM(D17:D18) -> 75 | E19: =SUM(E17:E18) -> 74 | F19: =SUM(F17:F18) -> 1 | G19: =E19/D19 -> 0.98666667 | H19: =SUM(H17:H18) -> 84 | I19: =SUM(I17:I18) -> 42 | J19: =SUM(J17:J18) -> 42 | K19: =I19/H19 -> 0.5 | L19: =SUM(L17:L18) -> 159 | M19: =SUM(M17:M18) -> 116 | N19: =SUM(N17:N18) -> 43 | O19: =M19/L19 -> 0.72955975 | Q19: =SUM(Q17:Q18) -> 15 | S19: =SUM(S17:S18) -> 10 | T19: =SUM(T17:T18) -> 18 | U19: =SUM(U17:U18) -> 28

Sheet Exported from SC 
A1: Task ID | B1: Asset - Tag | C1: Asset Pack ID | D1: Cable Pack ID | E1: Pipe Pack ID | F1: Loop Name | G1: Description | H1: Category (Summary) | I1: Discipline | J1: Task Type (Name) | K1: Discipline (Summary) | L1: Asset - Description | M1: Systemization - Process Plant ID | N1: Responsible Company (Summary) | O1: Actual Duration | P1: Scheduled Duration | Q1: Task Duration | R1: Title - Actual MH/Person | S1: Title - Planned MH/Person | T1: Field005 (Custom) | U1: Physical Location - Area (Summary) | V1: Systemization - Subsystem (Summary) | W1: Closing Date | X1: Subsystem ID | Y1: Task Priority | Z1: Priority | AA1: Test Form - Description | AB1: Asset Discipline | AC1: Task State | AD1: Subsystem Priority | AE1: Task Model | AF1: Closed By
A2: T-00018-0106 | B2: PS4-61-ISR-0101 | G2: CPX02 - Power transformer | H2: PCOM - Precommissioning | I2: E | J2: Conformity Check | K2: E - Electrical | L2: Shunt Reactor | M2: EACOP | N2: CPP AGI | Q2: 16 | T2: TZ-MID-67-SSF1-150259 | U2: PS4 - TZA - PS4 - Tanzania | V2: PS4-61-01 - 33kV Switchboard EITS Building (PS4-61-IJ-0001) | X2: PS4-61-01 | AA2: Power Transformer | AB2: E | AC2: To be completed | AD2: PS4 - Milestone D | AE2: TM-00018
A3: T-00018-0107 | B3: PS4-61-IU-0010 | G3: CPX02 - Power transformer | H3: PCOM - Precommissioning | I3: E | J3: Conformity Check | K3: E - Electrical | L3: LLHT Oil Transformer | M3: EACOP | N3: CPP AGI | Q3: 16 | T3: TZ-MID-67-SSF1-150259 | U3: PS4 - TZA - PS4 - Tanzania | V3: PS4-61-02 - 6.6kV Switchboard and Transformer LLHT North & South - EITS Building (PS4-61-IJ-0010) | X3: PS4-61-02 | AA3: Power Transformer | AB3: E | AC3: To be completed | AD3: PS4 - Milestone G | AE3: TM-00018
A4: T-00018-0108 | B4: PS4-61-IV-0001A | G4: CPX02 - Power transformer | H4: PCOM - Precommissioning | I4: E | J4: Conformity Check | K4: E - Electrical | L4: Distribution Transformer | M4: EACOP | N4: CPP AGI | Q4: 16 | S4: 16 | T4: TZ-MID-67-SSF1-150259 | U4: PS4 - TZA - PS4 - Tanzania | V4: PS4-61-06 - 0.4kV Switchboard EITS Building (PS4-61-IK-0001) | W4: 46205.474 | X4: PS4-61-06 | AA4: Power Transformer | AB4: E | AC4: Closed | AD4: PS4 - Milestone A | AE4: TM-00018 | AF4: sridhar, muthu
A5: T-00018-0109 | B5: PS4-61-IV-0001B | G5: CPX02 - Power transformer | H5: PCOM - Precommissioning | I5: E | J5: Conformity Check | K5: E - Electrical | L5: Distribution Transformer | M5: EACOP | N5: CPP AGI | Q5: 16 | T5: TZ-MID-67-SSF1-150259 | U5: PS4 - TZA - PS4 - Tanzania | V5: PS4-61-06 - 0.4kV Switchboard EITS Building (PS4-61-IK-0001) | W5: 46205.476 | X5: PS4-61-06 | AA5: Power Transformer | AB5: E | AC5: Closed | AD5: PS4 - Milestone A | AE5: TM-00018 | AF5: sridhar, muthu
A6: T-00018-0110 | B6: PS4-63-IV-0010 | G6: CPX02 - Power transformer | H6: PCOM - Precommissioning | I6: E | J6: Conformity Check | K6: E - Electrical | L6: Earthing Transformer | M6: EACOP | N6: CPP AGI | Q6: 16 | T6: TZ-MID-67-SSF1-150259 | U6: PS4 - TZA - PS4 - Tanzania | V6: PS4-61-01 - 33kV Switchboard EITS Building (PS4-61-IJ-0001) | X6: PS4-61-01 | AA6: Power Transformer | AB6: E | AC6: To be completed | AD6: PS4 - Milestone D | AE6: TM-00018
A7: T-00018-0111 | B7: PS4-63-IV-0011 | G7: CPX02 - Power transformer | H7: PCOM - Precommissioning | I7: E | J7: Conformity Check | K7: E - Electrical | L7: Earthing Transformer | M7: EACOP | N7: CPP AGI | Q7: 16 | T7: TZ-MID-67-SSF1-150259 | U7: PS4 - TZA - PS4 - Tanzania | V7: PS4-61-01 - 33kV Switchboard EITS Building (PS4-61-IJ-0001) | X7: PS4-61-01 | AA7: Power Transformer | AB7: E | AC7: To be completed | AD7: PS4 - Milestone D | AE7: TM-00018
A8: T-00018-0117 | B8: PS4-61-IV-0002A | G8: CPX02 - Power transformer | H8: PCOM - Precommissioning | I8: E | J8: Conformity Check | K8: E - Electrical | L8: Distribution Transformer | M8: EACOP | N8: CPP AGI | Q8: 16 | T8: TZ-MID-67-SSF1-150259 | U8: PS4 - TZA - PS4 - Tanzania | V8: PS4-61-01 - 33kV Switchboard EITS Building (PS4-61-IJ-0001) | X8: PS4-61-01 | AA8: Power Transformer | AB8: E | AC8: To be completed | AD8: PS4 - Milestone D | AE8: TM-00018
A9: T-00018-0118 | B9: PS4-61-IV-0002B | G9: CPX02 - Power transformer | H9: PCOM - Precommissioning | I9: E | J9: Conformity Check | K9: E - Electrical | L9: Distribution Transformer | M9: EACOP | N9: CPP AGI | Q9: 16 | T9: TZ-MID-67-SSF1-150259 | U9: PS4 - TZA - PS4 - Tanzania | V9: PS4-61-01 - 33kV Switchboard EITS Building (PS4-61-IJ-0001) | X9: PS4-61-01 | AA9: Power Transformer | AB9: E | AC9: To be completed | AD9: PS4 - Milestone D | AE9: TM-00018
A10: T-00018-0119 | B10: PS4-61-IV-0007A | G10: CPX02 - Power transformer | H10: PCOM - Precommissioning | I10: E | J10: Conformity Check | K10: E - Electrical | L10: Distribution Transformer | M10: EACOP | N10: CPP AGI | Q10: 16 | T10: TZ-MID-67-SSF1-150259 | U10: PS4 - TZA - PS4 - Tanzania | V10: PS4-61-01 - 33kV Switchboard EITS Building (PS4-61-IJ-0001) | X10: PS4-61-01 | AA10: Power Transformer | AB10: E | AC10: To be completed | AD10: PS4 - Milestone D | AE10: TM-00018
A11: T-00018-0120 | B11: PS4-61-IV-0007B | G11: CPX02 - Power transformer | H11: PCOM - Precommissioning | I11: E | J11: Conformity Check | K11: E - Electrical | L11: Distribution Transformer | M11: EACOP | N11: CPP AGI | Q11: 16 | T11: TZ-MID-67-SSF1-150259 | U11: PS4 - TZA - PS4 - Tanzania | V11: PS4-61-01 - 33kV Switchboard EITS Building (PS4-61-IJ-0001) | X11: PS4-61-01 | AA11: Power Transformer | AB11: E | AC11: To be completed | AD11: PS4 - Milestone D | AE11: TM-00018
A12: T-00018-0174 | B12: PS4-61-IU-3100A | G12: CPX02 - Power transformer | H12: PCOM - Precommissioning | I12: E | J12: Conformity Check | K12: E - Electrical | L12: VFD Transformer | M12: EACOP | N12: CPP AGI | Q12: 16 | U12: PS4 - TZA - PS4 - Tanzania | V12: PS4-25-02 - Crude Oil Export Pump A | X12: PS4-25-02 | AA12: Power Transformer | AB12: E | AC12: To be completed | AD12: PS4 - Milestone H | AE12: TM-00018
A13: T-00018-0175 | B13: PS4-61-IU-3100B | G13: CPX02 - Power transformer | H13: PCOM - Precommissioning | I13: E | J13: Conformity Check | K13: E - Electrical | L13: VFD Transformer | M13: EACOP | N13: CPP AGI | Q13: 16 | U13: PS4 - TZA - PS4 - Tanzania | V13: PS4-25-03 - Crude Oil Export Pump B | X13: PS4-25-03 | AA13: Power Transformer | AB13: E | AC13: To be completed | AD13: PS4 - Milestone H | AE13: TM-00018
A14: T-00018-0176 | B14: PS4-61-IU-3100C | G14: CPX02 - Power transformer | H14: PCOM - Precommissioning | I14: E | J14: Conformity Check | K14: E - Electrical | L14: VFD Transformer | M14: EACOP | N14: CPP AGI | Q14: 16 | U14: PS4 - TZA - PS4 - Tanzania | V14: PS4-25-04 - Crude Oil Export Pump C | X14: PS4-25-04 | AA14: Power Transformer | AB14: E | AC14: To be completed | AD14: PS4 - Milestone H | AE14: TM-00018
A15: T-00018-0185 | B15: PS4-61-IU-0001A | G15: CPX02 - Power transformer | H15: PCOM - Precommissioning | I15: E | J15: Conformity Check | K15: E - Electrical | L15: 11/33kV Transformer - 6.8 MVA | M15: EACOP | N15: CPP AGI | Q15: 16 | U15: PS4 - TZA - PS4 - Tanzania | V15: PS4-60-01 - Power Generation Package A | X15: PS4-60-01 | AA15: Power Transformer | AB15: E | AC15: To be completed | AD15: PS4 - Milestone B | AE15: TM-00018
A16: T-00018-0186 | B16: PS4-61-IU-0001B | G16: CPX02 - Power transformer | H16: PCOM - Precommissioning | I16: E | J16: Conformity Check | K16: E - Electrical | L16: 11/33kV Transformer - 6.8 MVA | M16: EACOP | N16: CPP AGI | Q16: 16 | U16: PS4 - TZA - PS4 - Tanzania | V16: PS4-60-04 - Power Generation Package B | X16: PS4-60-04 | AA16: Power Transformer | AB16: E | AC16: To be completed | AD16: PS4 - Milestone B | AE16: TM-00018
A17: T-00018-0187 | B17: PS4-61-IU-0001C | G17: CPX02 - Power transformer | H17: PCOM - Precommissioning | I17: E | J17: Conformity Check | K17: E - Electrical | L17: 11/33kV Transformer - 6.8 MVA | M17: EACOP | N17: CPP AGI | Q17: 16 | U17: PS4 - TZA - PS4 - Tanzania | V17: PS4-60-07 - Power Generation Package C | X17: PS4-60-07 | AA17: Power Transformer | AB17: E | AC17: To be completed | AD17: PS4 - Milestone D | AE17: TM-00018
A18: T-00018-0188 | B18: PS4-61-IU-0001D | G18: CPX02 - Power transformer | H18: PCOM - Precommissioning | I18: E | J18: Conformity Check | K18: E - Electrical | L18: 11/33kV Transformer - 6.8 MVA | M18: EACOP | N18: CPP AGI | Q18: 16 | U18: PS4 - TZA - PS4 - Tanzania | V18: PS4-60-10 - Power Generation Package D | X18: PS4-60-10 | AA18: Power Transformer | AB18: E | AC18: To be completed | AD18: PS4 - Milestone D | AE18: TM-00018
A19: T-00018-0189 | B19: PS4-61-IU-0001E | G19: CPX02 - Power transformer | H19: PCOM - Precommissioning | I19: E | J19: Conformity Check | K19: E - Electrical | L19: 11/33kV Transformer - 6.8 MVA | M19: EACOP | N19: CPP AGI | Q19: 16 | U19: PS4 - TZA - PS4 - Tanzania | V19: PS4-60-13 - Power Generation Package E | X19: PS4-60-13 | AA19: Power Transformer | AB19: E | AC19: To be completed | AD19: PS4 - Milestone D | AE19: TM-00018
A20: T-00018-0190 | B20: PS4-61-IU-0001F | G20: CPX02 - Power transformer | H20: PCOM - Precommissioning | I20: E | J20: Conformity Check | K20: E - Electrical | L20: 11/33kV Transformer - 6.8 MVA | M20: EACOP | N20: CPP AGI | Q20: 16 | U20: PS4 - TZA - PS4 - Tanzania | V20: PS4-60-16 - Power Generation Package F | X20: PS4-60-16 | AA20: Power Transformer | AB20: E | AC20: To be completed | AD20: PS4 - Milestone D | AE20: TM-00018
A21: T-00018-0191 | B21: PS4-61-IU-0001G | G21: CPX02 - Power transformer | H21: PCOM - Precommissioning | I21: E | J21: Conformity Check | K21: E - Electrical | L21: 11/33kV Transformer - 6.8 MVA | M21: EACOP | N21: CPP AGI | Q21: 16 | U21: PS4 - TZA - PS4 - Tanzania | V21: PS4-60-19 - Power Generation Package G | X21: PS4-60-19 | AA21: Power Transformer | AB21: E | AC21: To be completed | AD21: PS4 - Milestone E | AE21: TM-00018
A22: T-00018-0221 | B22: PS4-79-IV-0001 | G22: CPX02 - Power transformer | H22: PCOM - Precommissioning | I22: E | J22: Conformity Check | K22: E - Electrical | L22: Feeder to EHT Transformer / DB 1 | M22: EACOP | N22: CPP AGI | Q22: 16 | U22: PS4 - TZA - PS4 - Tanzania | V22: PS4-79-01 - Electrical Heat Tracing Transformer/Distribution Board 1 (PS4-79-IG-0001) | X22: PS4-79-01 | AA22: Power Transformer | AB22: E | AC22: To be completed | AD22: PS4 - Milestone H | AE22: TM-00018
A23: T-00018-0222 | B23: PS4-79-IV-0002 | G23: CPX02 - Power transformer | H23: PCOM - Precommissioning | I23: E | J23: Conformity Check | K23: E - Electrical | L23: Feeder to EHT Transformer / DB 2 | M23: EACOP | N23: CPP AGI | Q23: 16 | U23: PS4 - TZA - PS4 - Tanzania | V23: PS4-79-02 - Electrical Heat Tracing Transformer/Distribution Board 2 (PS4-79-IG-0002) | X23: PS4-79-02 | AA23: Power Transformer | AB23: E | AC23: To be completed | AD23: PS4 - Milestone H | AE23: TM-00018
... A36: T-00018-0235 | B36: PS4-87-IRF-0003 | G36: CPX02 - Power transformer | H36: PCOM - Precommissioning | I36: E | J36: Conformity Check | K36: E - Electrical | L36: Transformer Rectifier Unit 3-for tank (PS4-71-TR-4200) | M36: EACOP | N36: CPP AGI | Q36: 16 | U36: PS4 - TZA - PS4 - Tanzania | V36: PS4-71-12 - CFO Service Tank | X36: PS4-71-12 | AA36: Power Transformer | AB36: E | AC36: To be completed | AD36: PS4 - Milestone H | AE36: TM-00018
A37: T-00018-0236 | B37: PS4-87-IRF-0004 | G37: CPX02 - Power transformer | H37: PCOM - Precommissioning | I37: E | J37: Conformity Check | K37: E - Electrical | L37: Transformer Rectifier Unit 4-for tank ( PS4-71-TR-4400) | M37: EACOP | N37: CPP AGI | Q37: 16 | S37: 16 | U37: PS4 - TZA - PS4 - Tanzania | V37: PS4-71-15 - Diesel Fuel Storage Tank | X37: PS4-71-15 | AA37: Power Transformer | AB37: E | AC37: To be completed | AD37: PS4 - Milestone F | AE37: TM-00018
A38: T-00018-0292 | B38: PS4-61-IV-0005A | G38: CPX02 - Power transformer | H38: PCOM - Precommissioning | I38: E | J38: Conformity Check | K38: E - Electrical | L38: Distribution Transformer | M38: EACOP | N38: CPP AGI | Q38: 16 | S38: 16 | U38: PS4 - TZA - PS4 - Tanzania | V38: PS4-61-01 - 33kV Switchboard EITS Building (PS4-61-IJ-0001) | X38: PS4-61-01 | AA38: Power Transformer | AB38: E | AC38: To be completed | AD38: PS4 - Milestone D | AE38: TM-00018
A39: T-00018-0293 | B39: PS4-61-IV-0005B | G39: CPX02 - Power transformer | H39: PCOM - Precommissioning | I39: E | J39: Conformity Check | K39: E - Electrical | L39: Distribution Transformer | M39: EACOP | N39: CPP AGI | Q39: 16 | S39: 16 | U39: PS4 - TZA - PS4 - Tanzania | V39: PS4-61-01 - 33kV Switchboard EITS Building (PS4-61-IJ-0001) | X39: PS4-61-01 | AA39: Power Transformer | AB39: E | AC39: To be completed | AD39: PS4 - Milestone D | AE39: TM-00018
A40: T-00019-0033 | B40: PS4-61-IK-0003 | G40: CPX05 - LV switchboard | H40: PCOM - Precommissioning | I40: E | J40: Conformity Check | K40: E - Electrical | L40: LV SWGR | M40: EACOP | N40: CPP AGI | Q40: 24 | T40: TZ-MID-67-SSF1-150259 | U40: PS4 - TZA - PS4 - Tanzania | V40: PS4-61-04 - 0.4kV Switchboard Power Generator Building (PS4-61-IK-0003) | X40: PS4-61-04 | AA40: LV- Switchboard | AB40: E | AC40: To be completed | AD40: PS4 - Milestone B | AE40: TM-00019
